Workbook

Sheet Correlation_France
A1: CO2_Per_Capita | B1: GDP_Per_Capita | C1: Total_Renewable_% | F1: CO2_Per_Capita | G1: GDP_Per_Capita | H1: Total_Renewable_%
A2: 6.849684 | B2: 33409.68 | C2: 22488.796 | E2: CO2_Per_Capita | F2: 1
A3: 6.8707247 | B3: 33920.098 | C3: 22848.335 | E3: GDP_Per_Capita | F3: -0.75874597 | G3: 1
A4: 6.746978 | B4: 34152.773 | C4: 22590.446 | E4: Total_Renewable_% | F4: 0.93449676 | G4: -0.72415546 | H4: 1
A5: 6.799168 | B5: 34292.03 | C5: 22447.917
A6: 6.7686367 | B6: 35093.824 | C6: 22521.794
A7: 6.756068 | B7: 35495.465 | C7: 21984.393
A8: 6.5539103 | B8: 36166.16 | C8: 21919.931 | E8: t-statistic | F8: p-value
A9: 6.3502436 | B9: 36845.684 | C9: 21360.198 | E9: =(F3 * SQRT(21 - 2)) / SQRT(1 - (F3 * F3)) -> -5.0773179 | F9: =_xlfn.T.DIST.2T(ABS(E9), 21 - 2) -> 6.6912102e-05
A10: 6.2088747 | B10: 36761.793 | C10: 21385.374
A11: 5.8853593 | B11: 35534.926 | C11: 19748.154
A12: 5.945996 | B12: 36086.727 | C12: 20605.882
A13: 5.572035 | B13: 36691 | C13: 20400.403
A14: 5.59021 | B14: 36625.926 | C14: 20262.357
A15: 5.591334 | B15: 36647.22 | C15: 20482.069
A16: 5.067184 | B16: 36818.54 | C16: 20563.829
A17: 5.116293 | B17: 37077.89 | C17: 20319.297
A18: 5.1545954 | B18: 37343.84 | C18: 19032.143
A19: 5.182955 | B19: 38037.336 | C19: 18436.997
A20: 4.93138 | B20: 38555.465 | C20: 19601.777
A21: 4.812466 | B21: 39084.656 | C21: 18904.259
A22: 4.271517 | B22: 35913.82 | C22: 17563.421

Sheet Correlation_Spain
A1: CO2_Per_Capita | B1: GDP_Per_Capita | C1: Total_Renewable_% | F1: CO2_Per_Capita | G1: GDP_Per_Capita | H1: Total_Renewable_%
A2: 7.5392795 | B2: 26994.86 | C2: 6536.2108 | E2: CO2_Per_Capita | F2: 1
A3: 7.5409565 | B3: 28153.553 | C3: 7468.9365 | E3: GDP_Per_Capita | F3: -0.43284317 | G3: 1
A4: 7.9277363 | B4: 28753.322 | C4: 6253.464 | E4: Total_Renewable_% | F4: -0.8593137 | G4: 0.2313998 | H4: 1
A5: 7.8938184 | B5: 29371.865 | C5: 7374.7265
A6: 8.144856 | B6: 30088.092 | C6: 6960.0798
A7: 8.358881 | B7: 30885.602 | C7: 5908.992
A8: 8.029218 | B8: 31907.424 | C8: 6546.5038
A9: 8.051333 | B9: 32735.434 | C9: 6451.4832
A10: 7.2517366 | B10: 32844.324 | C10: 6735.6285
A11: 6.350556 | B11: 31669.691 | C11: 6926.3605 | E11: t-statistic | F11: p-value
A12: 6.032926 | B12: 31786.404 | C12: 8583.8168 | E12: =(F4 * SQRT(21 - 2)) / SQRT(1 - (F4 * F4)) -> -7.3236283 | F12: =_xlfn.T.DIST.2T(ABS(E12), 21 - 2) -> 6.0656264e-07
A13: 6.02738 | B13: 31600 | C13: 7686.3271
A14: 5.9005117 | B14: 30645.215 | C14: 7863.4021
A15: 5.3800054 | B15: 30327.451 | C15: 8862.8741
A16: 5.4292984 | B16: 30842.184 | C16: 8831.7483
A17: 5.7889185 | B17: 32057.098 | C17: 8060.0858
A18: 5.554019 | B18: 33002.676 | C18: 8471.1437
A19: 5.83512 | B19: 33924.137 | C19: 7461.3766
A20: 5.701944 | B20: 34553.625 | C20: 8120.9371
A21: 5.284558 | B21: 34957.465 | C21: 7773.0255
A22: 4.441423 | B22: 30834.514 | C22: 8592.1977

Sheet Correlation_Bulgaria
A1: CO2_Per_Capita | B1: GDP_Per_Capita | C1: Total_Renewable_% | F1: CO2_Per_Capita | G1: GDP_Per_Capita | H1: Total_Renewable_%
A2: 5.687045 | B2: 8410.795 | C2: 7224.8784 | E2: CO2_Per_Capita | F2: 1
A3: 6.1827483 | B3: 8832.291 | C3: 7387.8942 | E3: GDP_Per_Capita | F3: 0.038727975 | G3: 1
A4: 5.868906 | B4: 9471.766 | C4: 7784.3293 | E4: Total_Renewable_% | F4: -0.35879266 | G4: 0.30557652 | H4: 1
A5: 6.4695783 | B5: 10080.783 | C5: 7078.7241
A6: 6.3923783 | B6: 10853.785 | C6: 6978.3303
A7: 6.5757046 | B7: 11758.084 | C7: 8019.0579
A8: 6.784753 | B8: 12706.182 | C8: 8303.1585
A9: 7.3375487 | B9: 13785.228 | C9: 6141.5065
A10: 7.1694345 | B10: 14761.715 | C10: 6540.5152
A11: 6.1097956 | B11: 14363.259 | C11: 6634.5687 | E11: t-statistic | F11: p-value
A12: 6.4289203 | B12: 14686.461 | C12: 7344.6463 | E12: =(F4 * SQRT(21 - 2)) / SQRT(1 - (F4 * F4)) -> -1.6755003 | F12: =_xlfn.T.DIST.2T(ABS(E12), 21 - 2) -> 0.11021556
A13: 7.1978717 | B13: 15112 | C13: 7072.5648
A14: 6.5978446 | B14: 15314.524 | C14: 7383.6569
A15: 5.861707 | B15: 15314.154 | C15: 7383.5336
A16: 6.253115 | B16: 15550.346 | C16: 8121.6455
A17: 6.7052627 | B17: 16186.409 | C17: 8419.6536
A18: 6.3618603 | B18: 16795.824 | C18: 7920.6991
A19: 6.705518 | B19: 17386.271 | C19: 7518.9773
A20: 6.192869 | B20: 17982.424 | C20: 8474.9338
A21: 6.0490556 | B21: 18840.764 | C21: 7884.4444
A22: 5.274422 | B22: 18203.832 | C22: 7973.9925

Sheet Correlation_Denmark
A1: CO2_Per_Capita | B1: GDP_Per_Capita | C1: Total_Renewable_% | F1: CO2_Per_Capita | G1: GDP_Per_Capita | H1: Total_Renewable_%
A2: 10.170421 | B2: 39021.176 | C2: 2222.6761 | E2: CO2_Per_Capita | F2: 1
A3: 10.430784 | B3: 39425.863 | C3: 2234.5645 | E3: GDP_Per_Capita | F3: -0.832513 | G3: 1
A4: 10.33384 | B4: 39709.37 | C4: 2502.2677 | E4: Total_Renewable_% | F4: -0.96525413 | G4: 0.88196501 | H4: 1
A5: 11.250178 | B5: 39983.145 | C5: 2822.2914
A6: 10.195032 | B6: 41178.562 | C6: 3315.1814
A7: 9.509078 | B7: 42264.63 | C7: 3292.868
A8: 10.942724 | B8: 44025.484 | C8: 3016.1196
A9: 10.017085 | B9: 44481.47 | C9: 3507.0236
A10: 9.329914 | B10: 44246.4 | C10: 3340.9071
A11: 8.844816 | B11: 42090.17 | C11: 3204.4205 | E11: t-statistic | F11: p-value
A12: 8.866418 | B12: 42932.4 | C12: 3678.3222 | E12: =(F4 * SQRT(21 - 2)) / SQRT(1 - (F4 * F4)) -> -16.101174 | F12: =_xlfn.T.DIST.2T(ABS(E12), 21 - 2) -> 1.5731259e-12
A13: 7.9407773 | B13: 43575 | C13: 4560.2788
A14: 7.128379 | B14: 43509.613 | C14: 4789.3527
A15: 7.4373164 | B15: 43743.61 | C15: 5308.0073
A16: 6.6571136 | B16: 44215.633 | C16: 6171.7999
A17: 6.177417 | B17: 44940.887 | C17: 6572.3766
A18: 6.44471 | B18: 46018.984 | C18: 5941.1584
A19: 6.0127726 | B19: 47022.01 | C19: 6742.8078
A20: 5.973422 | B20: 47717.457 | C20: 6384.3025
A21: 5.3228407 | B21: 48238.656 | C21: 7292.1613
A22: 4.8528743 | B22: 47171.086 | C22: 7421.4742

Sheet Correlation_China
A1: CO2_Per_Capita | B1: GDP_Per_Capita | C1: Total_Renewable_% | F1: CO2_Per_Capita | G1: GDP_Per_Capita | H1: Total_Renewable_%
A2: 2.8700879 | B2: 4730.3545 | C2: 524.58004 | E2: CO2_Per_Capita | F2: 1
A3: 2.912365 | B3: 4995.1445 | C3: 638.69772 | E3: GDP_Per_Capita | F3: 0.90897084 | G3: 1
A4: 3.184619 | B4: 5343.1123 | C4: 668.46517 | E4: Total_Renewable_% | F4: 0.85955976 | G4: 0.99260745 | H4: 1
A5: 3.7351773 | B5: 5649.4634 | C5: 690.57324
A6: 4.001966 | B6: 6067.5913 | C6: 843.67929
A7: 4.4899764 | B7: 6626.592 | C7: 927.7799
A8: 4.921031 | B8: 7271.0356 | C8: 1003.0097
A9: 5.2606664 | B9: 7895.713 | C9: 1109.2894
A10: 5.6172485 | B10: 8190.1123 | C10: 1421.5237
A11: 5.8706574 | B11: 8734.041 | C11: 1395.0865 | E11: t-statistic | F11: p-value
A12: 6.370445 | B12: 9658.419 | C12: 1611.2263 | E12: =(F4 * SQRT(21 - 2)) / SQRT(1 - (F4 * F4)) -> 7.331655 | F12: =_xlfn.T.DIST.2T(ABS(E12), 21 - 2) -> 5.971589e-07
A13: 6.998823 | B13: 10221 | C13: 1622.596
A14: 7.131918 | B14: 10946.834 | C14: 2009.4258
A15: 7.2097993 | B15: 11731.295 | C15: 2165.742
A16: 7.187588 | B16: 12515.198 | C16: 2522.955
A17: 7.0609546 | B17: 13325.432 | C17: 2739.8722
A18: 6.9428844 | B18: 14138.955 | C18: 2995.3394
A19: 7.080384 | B19: 15030.447 | C19: 3249.1217
A20: 7.2915606 | B20: 15977.008 | C20: 3570.1935
A21: 7.5260706 | B21: 16879.54 | C21: 3913.2832
A22: 7.64075 | B22: 17225.969 | C22: 4182.1712

Sheet Regression_Bulgaria
A1: CO2_Per_Capita | B1: GDP_Per_Capita | C1: Total_Renewable_% | D1: Coal_% | F1: SUMMARY OUTPUT
A2: {=_xlfn.XLOOKUP($A2&$B2, 'CO2'!$A:$A&'CO2'!$C:$C, 'CO2'!$D:$D, "Missing")} -> 5.687045 | B2: {=_xlfn.XLOOKUP($A2&$B2, GDP!$A:$A&GDP!$C:$C, GDP!$D:$D, "Missing")} -> 8410.795 | C2: =SUM(Table5[[#This Row],[Nuclear]:[Wind]]) -> 3097.1012 | D2: {=_xlfn.XLOOKUP($A2&$B2, Energy!$A:$A&Energy!$C:$C, Energy!$D:$D, "Missing")} -> 9148.615
A3: {=_xlfn.XLOOKUP($A3&$B3, 'CO2'!$A:$A&'CO2'!$C:$C, 'CO2'!$D:$D, "Missing")} -> 6.1827483 | B3: {=_xlfn.XLOOKUP($A3&$B3, GDP!$A:$A&GDP!$C:$C, GDP!$D:$D, "Missing")} -> 8832.291 | C3: =SUM(Table5[[#This Row],[Nuclear]:[Wind]]) -> 3980.7987 | D3: {=_xlfn.XLOOKUP($A3&$B3, Energy!$A:$A&Energy!$C:$C, Energy!$D:$D, "Missing")} -> 10522.651 | F3: Regression Statistics
A4: {=_xlfn.XLOOKUP($A4&$B4, 'CO2'!$A:$A&'CO2'!$C:$C, 'CO2'!$D:$D, "Missing")} -> 5.868906 | B4: {=_xlfn.XLOOKUP($A4&$B4, GDP!$A:$A&GDP!$C:$C, GDP!$D:$D, "Missing")} -> 9471.766 | C4: =SUM(Table5[[#This Row],[Nuclear]:[Wind]]) -> 4299.7137 | D4: {=_xlfn.XLOOKUP($A4&$B4, Energy!$A:$A&Energy!$C:$C, Energy!$D:$D, "Missing")} -> 9772.364 | F4: Multiple R | G4: 0.94777581
A5: {=_xlfn.XLOOKUP($A5&$B5, 'CO2'!$A:$A&'CO2'!$C:$C, 'CO2'!$D:$D, "Missing")} -> 6.4695783 | B5: {=_xlfn.XLOOKUP($A5&$B5, GDP!$A:$A&GDP!$C:$C, GDP!$D:$D, "Missing")} -> 10080.783 | C5: =SUM(Table5[[#This Row],[Nuclear]:[Wind]]) -> 4872.8259 | D5: {=_xlfn.XLOOKUP($A5&$B5, Energy!$A:$A&Energy!$C:$C, Energy!$D:$D, "Missing")} -> 11021.766 | F5: R Square | G5: 0.89827898
A6: {=_xlfn.XLOOKUP($A6&$B6, 'CO2'!$A:$A&'CO2'!$C:$C, 'CO2'!$D:$D, "Missing")} -> 6.3923783 | B6: {=_xlfn.XLOOKUP($A6&$B6, GDP!$A:$A&GDP!$C:$C, GDP!$D:$D, "Missing")} -> 10853.785 | C6: =SUM(Table5[[#This Row],[Nuclear]:[Wind]]) -> 4962.8611 | D6: {=_xlfn.XLOOKUP($A6&$B6, Energy!$A:$A&Energy!$C:$C, Energy!$D:$D, "Missing")} -> 10606.762 | F6: Adjusted R Square | G6: 0.88032821
A7: {=_xlfn.XLOOKUP($A7&$B7, 'CO2'!$A:$A&'CO2'!$C:$C, 'CO2'!$D:$D, "Missing")} -> 6.5757046 | B7: {=_xlfn.XLOOKUP($A7&$B7, GDP!$A:$A&GDP!$C:$C, GDP!$D:$D, "Missing")} -> 11758.084 | C7: =SUM(Table5[[#This Row],[Nuclear]:[Wind]]) -> 4764.9936 | D7: {=_xlfn.XLOOKUP($A7&$B7, Energy!$A:$A&Energy!$C:$C, Energy!$D:$D, "Missing")} -> 10462.566 | F7: Standard Error | G7: 0.17611707
A8: {=_xlfn.XLOOKUP($A8&$B8, 'CO2'!$A:$A&'CO2'!$C:$C, 'CO2'!$D:$D, "Missing")} -> 6.784753 | B8: {=_xlfn.XLOOKUP($A8&$B8, GDP!$A:$A&GDP!$C:$C, GDP!$D:$D, "Missing")} -> 12706.182 | C8: =SUM(Table5[[#This Row],[Nuclear]:[Wind]]) -> 4461.316 | D8: {=_xlfn.XLOOKUP($A8&$B8, Energy!$A:$A&Energy!$C:$C, Energy!$D:$D, "Missing")} -> 10699.823 | F8: Observations | G8: 21
A9: {=_xlfn.XLOOKUP($A9&$B9, 'CO2'!$A:$A&'CO2'!$C:$C, 'CO2'!$D:$D, "Missing")} -> 7.3375487 | B9: {=_xlfn.XLOOKUP($A9&$B9, GDP!$A:$A&GDP!$C:$C, GDP!$D:$D, "Missing")} -> 13785.228 | C9: =SUM(Table5[[#This Row],[Nuclear]:[Wind]]) -> 4633.5461 | D9: {=_xlfn.XLOOKUP($A9&$B9, Energy!$A:$A&Energy!$C:$C, Energy!$D:$D, "Missing")} -> 12122.156
A10: {=_xlfn.XLOOKUP($A10&$B10, 'CO2'!$A:$A&'CO2'!$C:$C, 'CO2'!$D:$D, "Missing")} -> 7.1694345 | B10: {=_xlfn.XLOOKUP($A10&$B10, GDP!$A:$A&GDP!$C:$C, GDP!$D:$D, "Missing")} -> 14761.715 | C10: =SUM(Table5[[#This Row],[Nuclear]:[Wind]]) -> 5757.9007 | D10: {=_xlfn.XLOOKUP($A10&$B10, Energy!$A:$A&Energy!$C:$C, Energy!$D:$D, "Missing")} -> 11633.44 | F10: ANOVA
A11: {=_xlfn.XLOOKUP($A11&$B11, 'CO2'!$A:$A&'CO2'!$C:$C, 'CO2'!$D:$D, "Missing")} -> 6.1097956 | B11: {=_xlfn.XLOOKUP($A11&$B11, GDP!$A:$A&GDP!$C:$C, GDP!$D:$D, "Missing")} -> 14363.259 | C11: =SUM(Table5[[#This Row],[Nuclear]:[Wind]]) -> 5364.1494 | D11: {=_xlfn.XLOOKUP($A11&$B11, Energy!$A:$A&Energy!$C:$C, Energy!$D:$D, "Missing")} -> 9854.864 | G11: df | H11: SS | I11: MS | J11: F | K11: Significance F
A12: {=_xlfn.XLOOKUP($A12&$B12, 'CO2'!$A:$A&'CO2'!$C:$C, 'CO2'!$D:$D, "Missing")} -> 6.4289203 | B12: {=_xlfn.XLOOKUP($A12&$B12, GDP!$A:$A&GDP!$C:$C, GDP!$D:$D, "Missing")} -> 14686.461 | C12: =SUM(Table5[[#This Row],[Nuclear]:[Wind]]) -> 5130.5838 | D12: {=_xlfn.XLOOKUP($A12&$B12, Energy!$A:$A&Energy!$C:$C, Energy!$D:$D, "Missing")} -> 10762.482 | F12: Regression | G12: 3 | H12: 4.656422 | I12: 1.5521407 | J12: 50.041254 | K12: 1.1963792e-08
A13: {=_xlfn.XLOOKUP($A13&$B13, 'CO2'!$A:$A&'CO2'!$C:$C, 'CO2'!$D:$D, "Missing")} -> 7.1978717 | B13: {=_xlfn.XLOOKUP($A13&$B13, GDP!$A:$A&GDP!$C:$C, GDP!$D:$D, "Missing")} -> 15112 | C13: =SUM(Table5[[#This Row],[Nuclear]:[Wind]]) -> 4935.9722 | D13: {=_xlfn.XLOOKUP($A13&$B13, Energy!$A:$A&Energy!$C:$C, Energy!$D:$D, "Missing")} -> 12756.65 | F13: Residual | G13: 17 | H13: 0.52729277 | I13: 0.031017222
A14: {=_xlfn.XLOOKUP($A14&$B14, 'CO2'!$A:$A&'CO2'!$C:$C, 'CO2'!$D:$D, "Missing")} -> 6.5978446 | B14: {=_xlfn.XLOOKUP($A14&$B14, GDP!$A:$A&GDP!$C:$C, GDP!$D:$D, "Missing")} -> 15314.524 | C14: =SUM(Table5[[#This Row],[Nuclear]:[Wind]]) -> 4366.7018 | D14: {=_xlfn.XLOOKUP($A14&$B14, Energy!$A:$A&Energy!$C:$C, Energy!$D:$D, "Missing")} -> 10991.901 | F14: Total | G14: 20 | H14: 5.1837148
A15: {=_xlfn.XLOOKUP($A15&$B15, 'CO2'!$A:$A&'CO2'!$C:$C, 'CO2'!$D:$D, "Missing")} -> 5.861707 | B15: {=_xlfn.XLOOKUP($A15&$B15, GDP!$A:$A&GDP!$C:$C, GDP!$D:$D, "Missing")} -> 15314.154 | C15: =SUM(Table5[[#This Row],[Nuclear]:[Wind]]) -> 5170.6849 | D15: {=_xlfn.XLOOKUP($A15&$B15, Energy!$A:$A&Energy!$C:$C, Energy!$D:$D, "Missing")} -> 9515.395
A16: {=_xlfn.XLOOKUP($A16&$B16, 'CO2'!$A:$A&'CO2'!$C:$C, 'CO2'!$D:$D, "Missing")} -> 6.253115 | B16: {=_xlfn.XLOOKUP($A16&$B16, GDP!$A:$A&GDP!$C:$C, GDP!$D:$D, "Missing")} -> 15550.346 | C16: =SUM(Table5[[#This Row],[Nuclear]:[Wind]]) -> 5488.6111 | D16: {=_xlfn.XLOOKUP($A16&$B16, Energy!$A:$A&Energy!$C:$C, Energy!$D:$D, "Missing")} -> 10223.877 | G16: Coefficients | H16: Standard Error | I16: t Stat | J16: P-value | K16: Lower 95% | L16: Upper 95% | M16: Lower 95.0% | N16: Upper 95.0%
A17: {=_xlfn.XLOOKUP($A17&$B17, 'CO2'!$A:$A&'CO2'!$C:$C, 'CO2'!$D:$D, "Missing")} -> 6.7052627 | B17: {=_xlfn.XLOOKUP($A17&$B17, GDP!$A:$A&GDP!$C:$C, GDP!$D:$D, "Missing")} -> 16186.409 | C17: =SUM(Table5[[#This Row],[Nuclear]:[Wind]]) -> 6459.5416 | D17: {=_xlfn.XLOOKUP($A17&$B17, Energy!$A:$A&Energy!$C:$C, Energy!$D:$D, "Missing")} -> 10621.577 | F17: Intercept | G17: 1.1964408 | H17: 0.4850364 | I17: 2.4667032 | J17: 0.024563034 | K17: 0.17310347 | L17: 2.2197782 | M17: 0.17310347 | N17: 2.2197782
A18: {=_xlfn.XLOOKUP($A18&$B18, 'CO2'!$A:$A&'CO2'!$C:$C, 'CO2'!$D:$D, "Missing")} -> 6.3618603 | B18: {=_xlfn.XLOOKUP($A18&$B18, GDP!$A:$A&GDP!$C:$C, GDP!$D:$D, "Missing")} -> 16795.824 | C18: =SUM(Table5[[#This Row],[Nuclear]:[Wind]]) -> 7025.35 | D18: {=_xlfn.XLOOKUP($A18&$B18, Energy!$A:$A&Energy!$C:$C, Energy!$D:$D, "Missing")} -> 9291.52 | F18: GDP_Per_Capita | G18: 2.0600401e-05 | H18: 2.3914407e-05 | I18: 0.8614222 | J18: 0.40099307 | K18: -2.9854587e-05 | L18: 7.1055389e-05 | M18: -2.9854587e-05 | N18: 7.1055389e-05
A19: {=_xlfn.XLOOKUP($A19&$B19, 'CO2'!$A:$A&'CO2'!$C:$C, 'CO2'!$D:$D, "Missing")} -> 6.705518 | B19: {=_xlfn.XLOOKUP($A19&$B19, GDP!$A:$A&GDP!$C:$C, GDP!$D:$D, "Missing")} -> 17386.271 | C19: =SUM(Table5[[#This Row],[Nuclear]:[Wind]]) -> 6921.5408 | D19: {=_xlfn.XLOOKUP($A19&$B19, Energy!$A:$A&Energy!$C:$C, Energy!$D:$D, "Missing")} -> 10034.475 | F19: Total_Renewable_% | G19: 0.00012205685 | H19: 7.1858002e-05 | I19: 1.6985839 | J19: 0.1076235 | K19: -2.9550286e-05 | L19: 0.00027366398 | M19: -2.9550286e-05 | N19: 0.00027366398
A20: {=_xlfn.XLOOKUP($A20&$B20, 'CO2'!$A:$A&'CO2'!$C:$C, 'CO2'!$D:$D, "Missing")} -> 6.192869 | B20: {=_xlfn.XLOOKUP($A20&$B20, GDP!$A:$A&GDP!$C:$C, GDP!$D:$D, "Missing")} -> 17982.424 | C20: =SUM(Table5[[#This Row],[Nuclear]:[Wind]]) -> 6815.2586 | D20: {=_xlfn.XLOOKUP($A20&$B20, Energy!$A:$A&Energy!$C:$C, Energy!$D:$D, "Missing")} -> 9031.439 | F20: Coal_% | G20: 0.00041621823 | H20: 3.4832851e-05 | I20: 11.949014 | J20: 1.0739283e-09 | K20: 0.00034272734 | L20: 0.00048970913 | M20: 0.00034272734 | N20: 0.00048970913
A21: {=_xlfn.XLOOKUP($A21&$B21, 'CO2'!$A:$A&'CO2'!$C:$C, 'CO2'!$D:$D, "Missing")} -> 6.0490556 | B21: {=_xlfn.XLOOKUP($A21&$B21, GDP!$A:$A&GDP!$C:$C, GDP!$D:$D, "Missing")} -> 18840.764 | C21: =SUM(Table5[[#This Row],[Nuclear]:[Wind]]) -> 6385.7321 | D21: {=_xlfn.XLOOKUP($A21&$B21, Energy!$A:$A&Energy!$C:$C, Energy!$D:$D, "Missing")} -> 8480.807
A22: {=_xlfn.XLOOKUP($A22&$B22, 'CO2'!$A:$A&'CO2'!$C:$C, 'CO2'!$D:$D, "Missing")} -> 5.274422 | B22: {=_xlfn.XLOOKUP($A22&$B22, GDP!$A:$A&GDP!$C:$C, GDP!$D:$D, "Missing")} -> 18203.832 | C22: =SUM(Table5[[#This Row],[Nuclear]:[Wind]]) -> 7224.8784 | D22: {=_xlfn.XLOOKUP($A22&$B22, Energy!$A:$A&Energy!$C:$C, Energy!$D:$D, "Missing")} -> 6972.1484

Sheet Regression_Spain
A1: CO2_Per_Capita | B1: GDP_Per_Capita | C1: Total_Renewable_% | D1: Coal_% | F1: SUMMARY OUTPUT
A2: {=_xlfn.XLOOKUP($A2&$B2, 'CO2'!$A:$A&'CO2'!$C:$C, 'CO2'!$D:$D, "Missing")} -> 7.5392795 | B2: {=_xlfn.XLOOKUP($A2&$B2, GDP!$A:$A&GDP!$C:$C, GDP!$D:$D, "Missing")} -> 26994.86 | C2: =SUM(Table5[[#This Row],[Nuclear]:[Wind]]) -> 3097.1012 | D2: {=_xlfn.XLOOKUP($A2&$B2, Energy!$A:$A&Energy!$C:$C, Energy!$D:$D, "Missing")} -> 5935.813
A3: {=_xlfn.XLOOKUP($A3&$B3, 'CO2'!$A:$A&'CO2'!$C:$C, 'CO2'!$D:$D, "Missing")} -> 7.5409565 | B3: {=_xlfn.XLOOKUP($A3&$B3, GDP!$A:$A&GDP!$C:$C, GDP!$D:$D, "Missing")} -> 28153.553 | C3: =SUM(Table5[[#This Row],[Nuclear]:[Wind]]) -> 3980.7987 | D3: {=_xlfn.XLOOKUP($A3&$B3, Energy!$A:$A&Energy!$C:$C, Energy!$D:$D, "Missing")} -> 5404.7905 | F3: Regression Statistics
A4: {=_xlfn.XLOOKUP($A4&$B4, 'CO2'!$A:$A&'CO2'!$C:$C, 'CO2'!$D:$D, "Missing")} -> 7.9277363 | B4: {=_xlfn.XLOOKUP($A4&$B4, GDP!$A:$A&GDP!$C:$C, GDP!$D:$D, "Missing")} -> 28753.322 | C4: =SUM(Table5[[#This Row],[Nuclear]:[Wind]]) -> 4299.7137 | D4: {=_xlfn.XLOOKUP($A4&$B4, Energy!$A:$A&Energy!$C:$C, Energy!$D:$D, "Missing")} -> 6015.579 | F4: Multiple R | G4: 0.91778414
A5: {=_xlfn.XLOOKUP($A5&$B5, 'CO2'!$A:$A&'CO2'!$C:$C, 'CO2'!$D:$D, "Missing")} -> 7.8938184 | B5: {=_xlfn.XLOOKUP($A5&$B5, GDP!$A:$A&GDP!$C:$C, GDP!$D:$D, "Missing")} -> 29371.865 | C5: =SUM(Table5[[#This Row],[Nuclear]:[Wind]]) -> 4872.8259 | D5: {=_xlfn.XLOOKUP($A5&$B5, Energy!$A:$A&Energy!$C:$C, Energy!$D:$D, "Missing")} -> 5507.394 | F5: R Square | G5: 0.84232772
A6: {=_xlfn.XLOOKUP($A6&$B6, 'CO2'!$A:$A&'CO2'!$C:$C, 'CO2'!$D:$D, "Missing")} -> 8.144856 | B6: {=_xlfn.XLOOKUP($A6&$B6, GDP!$A:$A&GDP!$C:$C, GDP!$D:$D, "Missing")} -> 30088.092 | C6: =SUM(Table5[[#This Row],[Nuclear]:[Wind]]) -> 4962.8611 | D6: {=_xlfn.XLOOKUP($A6&$B6, Energy!$A:$A&Energy!$C:$C, Energy!$D:$D, "Missing")} -> 5662.134 | F6: Adjusted R Square | G6: 0.8145032
A7: {=_xlfn.XLOOKUP($A7&$B7, 'CO2'!$A:$A&'CO2'!$C:$C, 'CO2'!$D:$D, "Missing")} -> 8.358881 | B7: {=_xlfn.XLOOKUP($A7&$B7, GDP!$A:$A&GDP!$C:$C, GDP!$D:$D, "Missing")} -> 30885.602 | C7: =SUM(Table5[[#This Row],[Nuclear]:[Wind]]) -> 4764.9936 | D7: {=_xlfn.XLOOKUP($A7&$B7, Energy!$A:$A&Energy!$C:$C, Energy!$D:$D, "Missing")} -> 5427.03 | F7: Standard Error | G7: 0.51728836
A8: {=_xlfn.XLOOKUP($A8&$B8, 'CO2'!$A:$A&'CO2'!$C:$C, 'CO2'!$D:$D, "Missing")} -> 8.029218 | B8: {=_xlfn.XLOOKUP($A8&$B8, GDP!$A:$A&GDP!$C:$C, GDP!$D:$D, "Missing")} -> 31907.424 | C8: =SUM(Table5[[#This Row],[Nuclear]:[Wind]]) -> 4461.316 | D8: {=_xlfn.XLOOKUP($A8&$B8, Energy!$A:$A&Energy!$C:$C, Energy!$D:$D, "Missing")} -> 4659.76 | F8: Observations | G8: 21
A9: {=_xlfn.XLOOKUP($A9&$B9, 'CO2'!$A:$A&'CO2'!$C:$C, 'CO2'!$D:$D, "Missing")} -> 8.051333 | B9: {=_xlfn.XLOOKUP($A9&$B9, GDP!$A:$A&GDP!$C:$C, GDP!$D:$D, "Missing")} -> 32735.434 | C9: =SUM(Table5[[#This Row],[Nuclear]:[Wind]]) -> 4633.5461 | D9: {=_xlfn.XLOOKUP($A9&$B9, Energy!$A:$A&Energy!$C:$C, Energy!$D:$D, "Missing")} -> 5119.6885
A10: {=_xlfn.XLOOKUP($A10&$B10, 'CO2'!$A:$A&'CO2'!$C:$C, 'CO2'!$D:$D, "Missing")} -> 7.2517366 | B10: {=_xlfn.XLOOKUP($A10&$B10, GDP!$A:$A&GDP!$C:$C, GDP!$D:$D, "Missing")} -> 32844.324 | C10: =SUM(Table5[[#This Row],[Nuclear]:[Wind]]) -> 5757.9007 | D10: {=_xlfn.XLOOKUP($A10&$B10, Energy!$A:$A&Energy!$C:$C, Energy!$D:$D, "Missing")} -> 3396.8062 | F10: ANOVA
A11: {=_xlfn.XLOOKUP($A11&$B11, 'CO2'!$A:$A&'CO2'!$C:$C, 'CO2'!$D:$D, "Missing")} -> 6.350556 | B11: {=_xlfn.XLOOKUP($A11&$B11, GDP!$A:$A&GDP!$C:$C, GDP!$D:$D, "Missing")} -> 31669.691 | C11: =SUM(Table5[[#This Row],[Nuclear]:[Wind]]) -> 5364.1494 | D11: {=_xlfn.XLOOKUP($A11&$B11, Energy!$A:$A&Energy!$C:$C, Energy!$D:$D, "Missing")} -> 2351.6772 | G11: df | H11: SS | I11: MS | J11: F | K11: Significance F
A12: {=_xlfn.XLOOKUP($A12&$B12, 'CO2'!$A:$A&'CO2'!$C:$C, 'CO2'!$D:$D, "Missing")} -> 6.032926 | B12: {=_xlfn.XLOOKUP($A12&$B12, GDP!$A:$A&GDP!$C:$C, GDP!$D:$D, "Missing")} -> 31786.404 | C12: =SUM(Table5[[#This Row],[Nuclear]:[Wind]]) -> 5130.5838 | D12: {=_xlfn.XLOOKUP($A12&$B12, Energy!$A:$A&Energy!$C:$C, Energy!$D:$D, "Missing")} -> 1712.4531 | F12: Regression | G12: 3 | H12: 24.301891 | I12: 8.1006304 | J12: 30.272857 | K12: 4.8248842e-07
A13: {=_xlfn.XLOOKUP($A13&$B13, 'CO2'!$A:$A&'CO2'!$C:$C, 'CO2'!$D:$D, "Missing")} -> 6.02738 | B13: {=_xlfn.XLOOKUP($A13&$B13, GDP!$A:$A&GDP!$C:$C, GDP!$D:$D, "Missing")} -> 31600 | C13: =SUM(Table5[[#This Row],[Nuclear]:[Wind]]) -> 4935.9722 | D13: {=_xlfn.XLOOKUP($A13&$B13, Energy!$A:$A&Energy!$C:$C, Energy!$D:$D, "Missing")} -> 3165.2244 | F13: Residual | G13: 17 | H13: 4.5489831 | I13: 0.26758724
A14: {=_xlfn.XLOOKUP($A14&$B14, 'CO2'!$A:$A&'CO2'!$C:$C, 'CO2'!$D:$D, "Missing")} -> 5.9005117 | B14: {=_xlfn.XLOOKUP($A14&$B14, GDP!$A:$A&GDP!$C:$C, GDP!$D:$D, "Missing")} -> 30645.215 | C14: =SUM(Table5[[#This Row],[Nuclear]:[Wind]]) -> 4366.7018 | D14: {=_xlfn.XLOOKUP($A14&$B14, Energy!$A:$A&Energy!$C:$C, Energy!$D:$D, "Missing")} -> 3831.9521 | F14: Total | G14: 20 | H14: 28.850874
A15: {=_xlfn.XLOOKUP($A15&$B15, 'CO2'!$A:$A&'CO2'!$C:$C, 'CO2'!$D:$D, "Missing")} -> 5.3800054 | B15: {=_xlfn.XLOOKUP($A15&$B15, GDP!$A:$A&GDP!$C:$C, GDP!$D:$D, "Missing")} -> 30327.451 | C15: =SUM(Table5[[#This Row],[Nuclear]:[Wind]]) -> 5170.6849 | D15: {=_xlfn.XLOOKUP($A15&$B15, Energy!$A:$A&Energy!$C:$C, Energy!$D:$D, "Missing")} -> 2828.5532
A16: {=_xlfn.XLOOKUP($A16&$B16, 'CO2'!$A:$A&'CO2'!$C:$C, 'CO2'!$D:$D, "Missing")} -> 5.4292984 | B16: {=_xlfn.XLOOKUP($A16&$B16, GDP!$A:$A&GDP!$C:$C, GDP!$D:$D, "Missing")} -> 30842.184 | C16: =SUM(Table5[[#This Row],[Nuclear]:[Wind]]) -> 5488.6111 | D16: {=_xlfn.XLOOKUP($A16&$B16, Energy!$A:$A&Energy!$C:$C, Energy!$D:$D, "Missing")} -> 2897.2822 | G16: Coefficients | H16: Standard Error | I16: t Stat | J16: P-value | K16: Lower 95% | L16: Upper 95% | M16: Lower 95.0% | N16: Upper 95.0%
A17: {=_xlfn.XLOOKUP($A17&$B17, 'CO2'!$A:$A&'CO2'!$C:$C, 'CO2'!$D:$D, "Missing")} -> 5.7889185 | B17: {=_xlfn.XLOOKUP($A17&$B17, GDP!$A:$A&GDP!$C:$C, GDP!$D:$D, "Missing")} -> 32057.098 | C17: =SUM(Table5[[#This Row],[Nuclear]:[Wind]]) -> 6459.5416 | D17: {=_xlfn.XLOOKUP($A17&$B17, Energy!$A:$A&Energy!$C:$C, Energy!$D:$D, "Missing")} -> 3409.606 | F17: Intercept | G17: 0.024625486 | H17: 2.5025312 | I17: 0.0098402313 | J17: 0.99226331 | K17: -5.2552538 | L17: 5.3045048 | M17: -5.2552538 | N17: 5.3045048
A18: {=_xlfn.XLOOKUP($A18&$B18, 'CO2'!$A:$A&'CO2'!$C:$C, 'CO2'!$D:$D, "Missing")} -> 5.554019 | B18: {=_xlfn.XLOOKUP($A18&$B18, GDP!$A:$A&GDP!$C:$C, GDP!$D:$D, "Missing")} -> 33002.676 | C18: =SUM(Table5[[#This Row],[Nuclear]:[Wind]]) -> 7025.35 | D18: {=_xlfn.XLOOKUP($A18&$B18, Energy!$A:$A&Energy!$C:$C, Energy!$D:$D, "Missing")} -> 2612.0881 | F18: GDP_Per_Capita | G18: 0.00018579823 | H18: 8.6476466e-05 | I18: 2.148541 | J18: 0.046372121 | K18: 3.3488373e-06 | L18: 0.00036824763 | M18: 3.3488373e-06 | N18: 0.00036824763
A19: {=_xlfn.XLOOKUP($A19&$B19, 'CO2'!$A:$A&'CO2'!$C:$C, 'CO2'!$D:$D, "Missing")} -> 5.83512 | B19: {=_xlfn.XLOOKUP($A19&$B19, GDP!$A:$A&GDP!$C:$C, GDP!$D:$D, "Missing")} -> 33924.137 | C19: =SUM(Table5[[#This Row],[Nuclear]:[Wind]]) -> 6921.5408 | D19: {=_xlfn.XLOOKUP($A19&$B19, Energy!$A:$A&Energy!$C:$C, Energy!$D:$D, "Missing")} -> 3337.198 | F19: Total_Renewable_% | G19: -0.00031531985 | H19: 0.00018309859 | I19: -1.7221315 | J19: 0.10318831 | K19: -0.00070162411 | L19: 7.0984412e-05 | M19: -0.00070162411 | N19: 7.0984412e-05
A20: {=_xlfn.XLOOKUP($A20&$B20, 'CO2'!$A:$A&'CO2'!$C:$C, 'CO2'!$D:$D, "Missing")} -> 5.701944 | B20: {=_xlfn.XLOOKUP($A20&$B20, GDP!$A:$A&GDP!$C:$C, GDP!$D:$D, "Missing")} -> 34553.625 | C20: =SUM(Table5[[#This Row],[Nuclear]:[Wind]]) -> 6815.2586 | D20: {=_xlfn.XLOOKUP($A20&$B20, Energy!$A:$A&Energy!$C:$C, Energy!$D:$D, "Missing")} -> 2845.909 | F20: Coal_% | G20: 0.00065387055 | H20: 0.00010749579 | I20: 6.0827552 | J20: 1.2187533e-05 | K20: 0.00042707427 | L20: 0.00088066684 | M20: 0.00042707427 | N20: 0.00088066684
A21: {=_xlfn.XLOOKUP($A21&$B21, 'CO2'!$A:$A&'CO2'!$C:$C, 'CO2'!$D:$D, "Missing")} -> 5.284558 | B21: {=_xlfn.XLOOKUP($A21&$B21, GDP!$A:$A&GDP!$C:$C, GDP!$D:$D, "Missing")} -> 34957.465 | C21: =SUM(Table5[[#This Row],[Nuclear]:[Wind]]) -> 6385.7321 | D21: {=_xlfn.XLOOKUP($A21&$B21, Energy!$A:$A&Energy!$C:$C, Energy!$D:$D, "Missing")} -> 1243.4685
A22: {=_xlfn.XLOOKUP($A22&$B22, 'CO2'!$A:$A&'CO2'!$C:$C, 'CO2'!$D:$D, "Missing")} -> 4.441423 | B22: {=_xlfn.XLOOKUP($A22&$B22, GDP!$A:$A&GDP!$C:$C, GDP!$D:$D, "Missing")} -> 30834.514 | C22: =SUM(Table5[[#This Row],[Nuclear]:[Wind]]) -> 7224.8784 | D22: {=_xlfn.XLOOKUP($A22&$B22, Energy!$A:$A&Energy!$C:$C, Energy!$D:$D, "Missing")} -> 721.19147

Sheet Regression_Denmark
A1: CO2_Per_Capita | B1: GDP_Per_Capita | C1: Total_Renewable_% | D1: Coal_% | F1: SUMMARY OUTPUT
A2: {=_xlfn.XLOOKUP($A2&$B2, 'CO2'!$A:$A&'CO2'!$C:$C, 'CO2'!$D:$D, "Missing")} -> 10.170421 | B2: {=_xlfn.XLOOKUP($A2&$B2, GDP!$A:$A&GDP!$C:$C, GDP!$D:$D, "Missing")} -> 39021.176 | C2: =SUM(Table5[[#This Row],[Nuclear]:[Wind]]) -> 3097.1012 | D2: {=_xlfn.XLOOKUP($A2&$B2, Energy!$A:$A&Energy!$C:$C, Energy!$D:$D, "Missing")} -> 8649.004
A3: {=_xlfn.XLOOKUP($A3&$B3, 'CO2'!$A:$A&'CO2'!$C:$C, 'CO2'!$D:$D, "Missing")} -> 10.430784 | B3: {=_xlfn.XLOOKUP($A3&$B3, GDP!$A:$A&GDP!$C:$C, GDP!$D:$D, "Missing")} -> 39425.863 | C3: =SUM(Table5[[#This Row],[Nuclear]:[Wind]]) -> 3980.7987 | D3: {=_xlfn.XLOOKUP($A3&$B3, Energy!$A:$A&Energy!$C:$C, Energy!$D:$D, "Missing")} -> 9109.415 | F3: Regression Statistics
A4: {=_xlfn.XLOOKUP($A4&$B4, 'CO2'!$A:$A&'CO2'!$C:$C, 'CO2'!$D:$D, "Missing")} -> 10.33384 | B4: {=_xlfn.XLOOKUP($A4&$B4, GDP!$A:$A&GDP!$C:$C, GDP!$D:$D, "Missing")} -> 39709.37 | C4: =SUM(Table5[[#This Row],[Nuclear]:[Wind]]) -> 4299.7137 | D4: {=_xlfn.XLOOKUP($A4&$B4, Energy!$A:$A&Energy!$C:$C, Energy!$D:$D, "Missing")} -> 9091.186 | F4: Multiple R | G4: 0.98393919
A5: {=_xlfn.XLOOKUP($A5&$B5, 'CO2'!$A:$A&'CO2'!$C:$C, 'CO2'!$D:$D, "Missing")} -> 11.250178 | B5: {=_xlfn.XLOOKUP($A5&$B5, GDP!$A:$A&GDP!$C:$C, GDP!$D:$D, "Missing")} -> 39983.145 | C5: =SUM(Table5[[#This Row],[Nuclear]:[Wind]]) -> 4872.8259 | D5: {=_xlfn.XLOOKUP($A5&$B5, Energy!$A:$A&Energy!$C:$C, Energy!$D:$D, "Missing")} -> 12370.176 | F5: R Square | G5: 0.96813634
A6: {=_xlfn.XLOOKUP($A6&$B6, 'CO2'!$A:$A&'CO2'!$C:$C, 'CO2'!$D:$D, "Missing")} -> 10.195032 | B6: {=_xlfn.XLOOKUP($A6&$B6, GDP!$A:$A&GDP!$C:$C, GDP!$D:$D, "Missing")} -> 41178.562 | C6: =SUM(Table5[[#This Row],[Nuclear]:[Wind]]) -> 4962.8611 | D6: {=_xlfn.XLOOKUP($A6&$B6, Energy!$A:$A&Energy!$C:$C, Energy!$D:$D, "Missing")} -> 9457.481 | F6: Adjusted R Square | G6: 0.96251334
A7: {=_xlfn.XLOOKUP($A7&$B7, 'CO2'!$A:$A&'CO2'!$C:$C, 'CO2'!$D:$D, "Missing")} -> 9.509078 | B7: {=_xlfn.XLOOKUP($A7&$B7, GDP!$A:$A&GDP!$C:$C, GDP!$D:$D, "Missing")} -> 42264.63 | C7: =SUM(Table5[[#This Row],[Nuclear]:[Wind]]) -> 4764.9936 | D7: {=_xlfn.XLOOKUP($A7&$B7, Energy!$A:$A&Energy!$C:$C, Energy!$D:$D, "Missing")} -> 7943.855 | F7: Standard Error | G7: 0.39159837
A8: {=_xlfn.XLOOKUP($A8&$B8, 'CO2'!$A:$A&'CO2'!$C:$C, 'CO2'!$D:$D, "Missing")} -> 10.942724 | B8: {=_xlfn.XLOOKUP($A8&$B8, GDP!$A:$A&GDP!$C:$C, GDP!$D:$D, "Missing")} -> 44025.484 | C8: =SUM(Table5[[#This Row],[Nuclear]:[Wind]]) -> 4461.316 | D8: {=_xlfn.XLOOKUP($A8&$B8, Energy!$A:$A&Energy!$C:$C, Energy!$D:$D, "Missing")} -> 11905.475 | F8: Observations | G8: 21
A9: {=_xlfn.XLOOKUP($A9&$B9, 'CO2'!$A:$A&'CO2'!$C:$C, 'CO2'!$D:$D, "Missing")} -> 10.017085 | B9: {=_xlfn.XLOOKUP($A9&$B9, GDP!$A:$A&GDP!$C:$C, GDP!$D:$D, "Missing")} -> 44481.47 | C9: =SUM(Table5[[#This Row],[Nuclear]:[Wind]]) -> 4633.5461 | D9: {=_xlfn.XLOOKUP($A9&$B9, Energy!$A:$A&Energy!$C:$C, Energy!$D:$D, "Missing")} -> 9930.383
A10: {=_xlfn.XLOOKUP($A10&$B10, 'CO2'!$A:$A&'CO2'!$C:$C, 'CO2'!$D:$D, "Missing")} -> 9.329914 | B10: {=_xlfn.XLOOKUP($A10&$B10, GDP!$A:$A&GDP!$C:$C, GDP!$D:$D, "Missing")} -> 44246.4 | C10: =SUM(Table5[[#This Row],[Nuclear]:[Wind]]) -> 5757.9007 | D10: {=_xlfn.XLOOKUP($A10&$B10, Energy!$A:$A&Energy!$C:$C, Energy!$D:$D, "Missing")} -> 8675.162 | F10: ANOVA
A11: {=_xlfn.XLOOKUP($A11&$B11, 'CO2'!$A:$A&'CO2'!$C:$C, 'CO2'!$D:$D, "Missing")} -> 8.844816 | B11: {=_xlfn.XLOOKUP($A11&$B11, GDP!$A:$A&GDP!$C:$C, GDP!$D:$D, "Missing")} -> 42090.17 | C11: =SUM(Table5[[#This Row],[Nuclear]:[Wind]]) -> 5364.1494 | D11: {=_xlfn.XLOOKUP($A11&$B11, Energy!$A:$A&Energy!$C:$C, Energy!$D:$D, "Missing")} -> 8473.453 | G11: df | H11: SS | I11: MS | J11: F | K11: Significance F
A12: {=_xlfn.XLOOKUP($A12&$B12, 'CO2'!$A:$A&'CO2'!$C:$C, 'CO2'!$D:$D, "Missing")} -> 8.866418 | B12: {=_xlfn.XLOOKUP($A12&$B12, GDP!$A:$A&GDP!$C:$C, GDP!$D:$D, "Missing")} -> 42932.4 | C12: =SUM(Table5[[#This Row],[Nuclear]:[Wind]]) -> 5130.5838 | D12: {=_xlfn.XLOOKUP($A12&$B12, Energy!$A:$A&Energy!$C:$C, Energy!$D:$D, "Missing")} -> 8196.313 | F12: Regression | G12: 3 | H12: 79.208451 | I12: 26.402817 | J12: 172.17438 | K12: 6.417074e-13
A13: {=_xlfn.XLOOKUP($A13&$B13, 'CO2'!$A:$A&'CO2'!$C:$C, 'CO2'!$D:$D, "Missing")} -> 7.9407773 | B13: {=_xlfn.XLOOKUP($A13&$B13, GDP!$A:$A&GDP!$C:$C, GDP!$D:$D, "Missing")} -> 43575 | C13: =SUM(Table5[[#This Row],[Nuclear]:[Wind]]) -> 4935.9722 | D13: {=_xlfn.XLOOKUP($A13&$B13, Energy!$A:$A&Energy!$C:$C, Energy!$D:$D, "Missing")} -> 6791.62 | F13: Residual | G13: 17 | H13: 2.6069378 | I13: 0.15334928
A14: {=_xlfn.XLOOKUP($A14&$B14, 'CO2'!$A:$A&'CO2'!$C:$C, 'CO2'!$D:$D, "Missing")} -> 7.128379 | B14: {=_xlfn.XLOOKUP($A14&$B14, GDP!$A:$A&GDP!$C:$C, GDP!$D:$D, "Missing")} -> 43509.613 | C14: =SUM(Table5[[#This Row],[Nuclear]:[Wind]]) -> 4366.7018 | D14: {=_xlfn.XLOOKUP($A14&$B14, Energy!$A:$A&Energy!$C:$C, Energy!$D:$D, "Missing")} -> 5303.908 | F14: Total | G14: 20 | H14: 81.815389
A15: {=_xlfn.XLOOKUP($A15&$B15, 'CO2'!$A:$A&'CO2'!$C:$C, 'CO2'!$D:$D, "Missing")} -> 7.4373164 | B15: {=_xlfn.XLOOKUP($A15&$B15, GDP!$A:$A&GDP!$C:$C, GDP!$D:$D, "Missing")} -> 43743.61 | C15: =SUM(Table5[[#This Row],[Nuclear]:[Wind]]) -> 5170.6849 | D15: {=_xlfn.XLOOKUP($A15&$B15, Energy!$A:$A&Energy!$C:$C, Energy!$D:$D, "Missing")} -> 6708.5737
A16: {=_xlfn.XLOOKUP($A16&$B16, 'CO2'!$A:$A&'CO2'!$C:$C, 'CO2'!$D:$D, "Missing")} -> 6.6571136 | B16: {=_xlfn.XLOOKUP($A16&$B16, GDP!$A:$A&GDP!$C:$C, GDP!$D:$D, "Missing")} -> 44215.633 | C16: =SUM(Table5[[#This Row],[Nuclear]:[Wind]]) -> 5488.6111 | D16: {=_xlfn.XLOOKUP($A16&$B16, Energy!$A:$A&Energy!$C:$C, Energy!$D:$D, "Missing")} -> 5290.3877 | G16: Coefficients | H16: Standard Error | I16: t Stat | J16: P-value | K16: Lower 95% | L16: Upper 95% | M16: Lower 95.0% | N16: Upper 95.0%
A17: {=_xlfn.XLOOKUP($A17&$B17, 'CO2'!$A:$A&'CO2'!$C:$C, 'CO2'!$D:$D, "Missing")} -> 6.177417 | B17: {=_xlfn.XLOOKUP($A17&$B17, GDP!$A:$A&GDP!$C:$C, GDP!$D:$D, "Missing")} -> 44940.887 | C17: =SUM(Table5[[#This Row],[Nuclear]:[Wind]]) -> 6459.5416 | D17: {=_xlfn.XLOOKUP($A17&$B17, Energy!$A:$A&Energy!$C:$C, Energy!$D:$D, "Missing")} -> 3736.6948 | F17: Intercept | G17: 10.090049 | H17: 2.6107546 | I17: 3.8648018 | J17: 0.0012430984 | K17: 4.5818384 | L17: 15.59826 | M17: 4.5818384 | N17: 15.59826
A18: {=_xlfn.XLOOKUP($A18&$B18, 'CO2'!$A:$A&'CO2'!$C:$C, 'CO2'!$D:$D, "Missing")} -> 6.44471 | B18: {=_xlfn.XLOOKUP($A18&$B18, GDP!$A:$A&GDP!$C:$C, GDP!$D:$D, "Missing")} -> 46018.984 | C18: =SUM(Table5[[#This Row],[Nuclear]:[Wind]]) -> 7025.35 | D18: {=_xlfn.XLOOKUP($A18&$B18, Energy!$A:$A&Energy!$C:$C, Energy!$D:$D, "Missing")} -> 4290.6 | F18: GDP_Per_Capita | G18: -0.00011113162 | H18: 6.5548643e-05 | I18: -1.6954069 | J18: 0.10823431 | K18: -0.00024942717 | L18: 2.7163924e-05 | M18: -0.00024942717 | N18: 2.7163924e-05
A19: {=_xlfn.XLOOKUP($A19&$B19, 'CO2'!$A:$A&'CO2'!$C:$C, 'CO2'!$D:$D, "Missing")} -> 6.0127726 | B19: {=_xlfn.XLOOKUP($A19&$B19, GDP!$A:$A&GDP!$C:$C, GDP!$D:$D, "Missing")} -> 47022.01 | C19: =SUM(Table5[[#This Row],[Nuclear]:[Wind]]) -> 6921.5408 | D19: {=_xlfn.XLOOKUP($A19&$B19, Energy!$A:$A&Energy!$C:$C, Energy!$D:$D, "Missing")} -> 3186.1675 | F19: Total_Renewable_% | G19: -0.00011552809 | H19: 0.00015576109 | I19: -0.74170056 | J19: 0.46839259 | K19: -0.00044415526 | L19: 0.00021309909 | M19: -0.00044415526 | N19: 0.00021309909
A20: {=_xlfn.XLOOKUP($A20&$B20, 'CO2'!$A:$A&'CO2'!$C:$C, 'CO2'!$D:$D, "Missing")} -> 5.973422 | B20: {=_xlfn.XLOOKUP($A20&$B20, GDP!$A:$A&GDP!$C:$C, GDP!$D:$D, "Missing")} -> 47717.457 | C20: =SUM(Table5[[#This Row],[Nuclear]:[Wind]]) -> 6815.2586 | D20: {=_xlfn.XLOOKUP($A20&$B20, Energy!$A:$A&Energy!$C:$C, Energy!$D:$D, "Missing")} -> 3240.1475 | F20: Coal_% | G20: 0.00052579196 | H20: 4.6405588e-05 | I20: 11.330359 | J20: 2.4096671e-09 | K20: 0.00042788473 | L20: 0.0006236992 | M20: 0.00042788473 | N20: 0.0006236992
A21: {=_xlfn.XLOOKUP($A21&$B21, 'CO2'!$A:$A&'CO2'!$C:$C, 'CO2'!$D:$D, "Missing")} -> 5.3228407 | B21: {=_xlfn.XLOOKUP($A21&$B21, GDP!$A:$A&GDP!$C:$C, GDP!$D:$D, "Missing")} -> 48238.656 | C21: =SUM(Table5[[#This Row],[Nuclear]:[Wind]]) -> 6385.7321 | D21: {=_xlfn.XLOOKUP($A21&$B21, Energy!$A:$A&Energy!$C:$C, Energy!$D:$D, "Missing")} -> 1818.7543
A22: {=_xlfn.XLOOKUP($A22&$B22, 'CO2'!$A:$A&'CO2'!$C:$C, 'CO2'!$D:$D, "Missing")} -> 4.8528743 | B22: {=_xlfn.XLOOKUP($A22&$B22, GDP!$A:$A&GDP!$C:$C, GDP!$D:$D, "Missing")} -> 47171.086 | C22: =SUM(Table5[[#This Row],[Nuclear]:[Wind]]) -> 7224.8784 | D22: {=_xlfn.XLOOKUP($A22&$B22, Energy!$A:$A&Energy!$C:$C, Energy!$D:$D, "Missing")} -> 1596.481

Sheet Master
A1: Country | B1: Year | C1: CO2_Per_Capita | D1: GDP_Per_Capita | E1: Life_Expectancy | F1: Coal | G1: Natural gas | H1: Nuclear | I1: Hydro | J1: Solar | K1: Wind | L1: Total_Renewable
A2: Bulgaria | B2: 1980 | C2: {=_xlfn.XLOOKUP($A2&$B2, 'CO2'!$A:$A&'CO2'!$C:$C, 'CO2'!$D:$D, "Missing")} -> 8.719879 | D2: {=_xlfn.XLOOKUP($A2&$B2, GDP!$A:$A&GDP!$C:$C, GDP!$D:$D, "Missing")} -> 9634 | E2: {=_xlfn.XLOOKUP($A2&$B2, LifeExp!$A:$A&LifeExp!$C:$C, LifeExp!$D:$D, "Missing")} -> 71.0809 | F2: {=_xlfn.XLOOKUP($A2&$B2, Energy!$A:$A&Energy!$C:$C, Energy!$D:$D, "Missing")} -> 11908.899 | G2: {=_xlfn.XLOOKUP($A2&$B2, Energy!$A:$A&Energy!$C:$C, Energy!$F:$F, "Missing")} -> 4175.33 | H2: {=_xlfn.XLOOKUP($A2&$B2, Energy!$A:$A&Energy!$C:$C, Energy!$G:$G, "Missing")} -> 1932.9448 | I2: {=_xlfn.XLOOKUP($A2&$B2, Energy!$A:$A&Energy!$C:$C, Energy!$H:$H, "Missing")} -> 1164.1564 | J2: {=_xlfn.XLOOKUP($A2&$B2, Energy!$A:$A&Energy!$C:$C, Energy!$J:$J, "Missing")} -> 0 | K2: {=_xlfn.XLOOKUP($A2&$B2, Energy!$A:$A&Energy!$C:$C, Energy!$I:$I, "Missing")} -> 0 | L2: =SUM(Table5[[#This Row],[Nuclear]:[Wind]]) -> 3097.1012
A3: Bulgaria | B3: 1981 | C3: {=_xlfn.XLOOKUP($A3&$B3, 'CO2'!$A:$A&'CO2'!$C:$C, 'CO2'!$D:$D, "Missing")} -> 9.011264 | D3: {=_xlfn.XLOOKUP($A3&$B3, GDP!$A:$A&GDP!$C:$C, GDP!$D:$D, "Missing")} -> 9860 | E3: {=_xlfn.XLOOKUP($A3&$B3, LifeExp!$A:$A&LifeExp!$C:$C, LifeExp!$D:$D, "Missing")} -> 71.4778 | F3: {=_xlfn.XLOOKUP($A3&$B3, Energy!$A:$A&Energy!$C:$C, Energy!$D:$D, "Missing")} -> 12054.223 | G3: {=_xlfn.XLOOKUP($A3&$B3, Energy!$A:$A&Energy!$C:$C, Energy!$F:$F, "Missing")} -> 4527.4688 | H3: {=_xlfn.XLOOKUP($A3&$B3, Energy!$A:$A&Energy!$C:$C, Energy!$G:$G, "Missing")} -> 2850.0356 | I3: {=_xlfn.XLOOKUP($A3&$B3, Energy!$A:$A&Energy!$C:$C, Energy!$H:$H, "Missing")} -> 1130.7631 | J3: {=_xlfn.XLOOKUP($A3&$B3, Energy!$A:$A&Energy!$C:$C, Energy!$J:$J, "Missing")} -> 0 | K3: {=_xlfn.XLOOKUP($A3&$B3, Energy!$A:$A&Energy!$C:$C, Energy!$I:$I, "Missing")} -> 0 | L3: =SUM(Table5[[#This Row],[Nuclear]:[Wind]]) -> 3980.7987
A4: Bulgaria | B4: 1982 | C4: {=_xlfn.XLOOKUP($A4&$B4, 'CO2'!$A:$A&'CO2'!$C:$C, 'CO2'!$D:$D, "Missing")} -> 10.080424 | D4: {=_xlfn.XLOOKUP($A4&$B4, GDP!$A:$A&GDP!$C:$C, GDP!$D:$D, "Missing")} -> 10154 | E4: {=_xlfn.XLOOKUP($A4&$B4, LifeExp!$A:$A&LifeExp!$C:$C, LifeExp!$D:$D, "Missing")} -> 71.0775 | F4: {=_xlfn.XLOOKUP($A4&$B4, Energy!$A:$A&Energy!$C:$C, Energy!$D:$D, "Missing")} -> 12628.571 | G4: {=_xlfn.XLOOKUP($A4&$B4, Energy!$A:$A&Energy!$C:$C, Energy!$F:$F, "Missing")} -> 4995.9956 | H4: {=_xlfn.XLOOKUP($A4&$B4, Energy!$A:$A&Energy!$C:$C, Energy!$G:$G, "Missing")} -> 3349.1392 | I4: {=_xlfn.XLOOKUP($A4&$B4, Energy!$A:$A&Energy!$C:$C, Energy!$H:$H, "Missing")} -> 950.57446 | J4: {=_xlfn.XLOOKUP($A4&$B4, Energy!$A:$A&Energy!$C:$C, Energy!$J:$J, "Missing")} -> 0 | K4: {=_xlfn.XLOOKUP($A4&$B4, Energy!$A:$A&Energy!$C:$C, Energy!$I:$I, "Missing")} -> 0 | L4: =SUM(Table5[[#This Row],[Nuclear]:[Wind]]) -> 4299.7137
A5: Bulgaria | B5: 1983 | C5: {=_xlfn.XLOOKUP($A5&$B5, 'CO2'!$A:$A&'CO2'!$C:$C, 'CO2'!$D:$D, "Missing")} -> 10.081495 | D5: {=_xlfn.XLOOKUP($A5&$B5, GDP!$A:$A&GDP!$C:$C, GDP!$D:$D, "Missing")} -> 9942 | E5: {=_xlfn.XLOOKUP($A5&$B5, LifeExp!$A:$A&LifeExp!$C:$C, LifeExp!$D:$D, "Missing")} -> 71.2393 | F5: {=_xlfn.XLOOKUP($A5&$B5, Energy!$A:$A&Energy!$C:$C, Energy!$D:$D, "Missing")} -> 12551.295 | G5: {=_xlfn.XLOOKUP($A5&$B5, Energy!$A:$A&Energy!$C:$C, Energy!$F:$F, "Missing")} -> 5237.634 | H5: {=_xlfn.XLOOKUP($A5&$B5, Energy!$A:$A&Energy!$C:$C, Energy!$G:$G, "Missing")} -> 3830.2258 | I5: {=_xlfn.XLOOKUP($A5&$B5, Energy!$A:$A&Energy!$C:$C, Energy!$H:$H, "Missing")} -> 1042.6001 | J5: {=_xlfn.XLOOKUP($A5&$B5, Energy!$A:$A&Energy!$C:$C, Energy!$J:$J, "Missing")} -> 0 | K5: {=_xlfn.XLOOKUP($A5&$B5, Energy!$A:$A&Energy!$C:$C, Energy!$I:$I, "Missing")} -> 0 | L5: =SUM(Table5[[#This Row],[Nuclear]:[Wind]]) -> 4872.8259
A6: Bulgaria | B6: 1984 | C6: {=_xlfn.XLOOKUP($A6&$B6, 'CO2'!$A:$A&'CO2'!$C:$C, 'CO2'!$D:$D, "Missing")} -> 9.722857 | D6: {=_xlfn.XLOOKUP($A6&$B6, GDP!$A:$A&GDP!$C:$C, GDP!$D:$D, "Missing")} -> 10249 | E6: {=_xlfn.XLOOKUP($A6&$B6, LifeExp!$A:$A&LifeExp!$C:$C, LifeExp!$D:$D, "Missing")} -> 71.3472 | F6: {=_xlfn.XLOOKUP($A6&$B6, Energy!$A:$A&Energy!$C:$C, Energy!$D:$D, "Missing")} -> 12543.75 | G6: {=_xlfn.XLOOKUP($A6&$B6, Energy!$A:$A&Energy!$C:$C, Energy!$F:$F, "Missing")} -> 5495.047 | H6: {=_xlfn.XLOOKUP($A6&$B6, Energy!$A:$A&Energy!$C:$C, Energy!$G:$G, "Missing")} -> 3951.362 | I6: {=_xlfn.XLOOKUP($A6&$B6, Energy!$A:$A&Energy!$C:$C, Energy!$H:$H, "Missing")} -> 1011.4991 | J6: {=_xlfn.XLOOKUP($A6&$B6, Energy!$A:$A&Energy!$C:$C, Energy!$J:$J, "Missing")} -> 0 | K6: {=_xlfn.XLOOKUP($A6&$B6, Energy!$A:$A&Energy!$C:$C, Energy!$I:$I, "Missing")} -> 0 | L6: =SUM(Table5[[#This Row],[Nuclear]:[Wind]]) -> 4962.8611
A7: Bulgaria | B7: 1985 | C7: {=_xlfn.XLOOKUP($A7&$B7, 'CO2'!$A:$A&'CO2'!$C:$C, 'CO2'!$D:$D, "Missing")} -> 9.959011 | D7: {=_xlfn.XLOOKUP($A7&$B7, GDP!$A:$A&GDP!$C:$C, GDP!$D:$D, "Missing")} -> 9924 | E7: {=_xlfn.XLOOKUP($A7&$B7, LifeExp!$A:$A&LifeExp!$C:$C, LifeExp!$D:$D, "Missing")} -> 71.0482 | F7: {=_xlfn.XLOOKUP($A7&$B7, Energy!$A:$A&Energy!$C:$C, Energy!$D:$D, "Missing")} -> 13082.825 | G7: {=_xlfn.XLOOKUP($A7&$B7, Energy!$A:$A&Energy!$C:$C, Energy!$F:$F, "Missing")} -> 5989.3813 | H7: {=_xlfn.XLOOKUP($A7&$B7, Energy!$A:$A&Energy!$C:$C, Energy!$G:$G, "Missing")} -> 4071.3906 | I7: {=_xlfn.XLOOKUP($A7&$B7, Energy!$A:$A&Energy!$C:$C, Energy!$H:$H, "Missing")} -> 693.60297 | J7: {=_xlfn.XLOOKUP($A7&$B7, Energy!$A:$A&Energy!$C:$C, Energy!$J:$J, "Missing")} -> 0 | K7: {=_xlfn.XLOOKUP($A7&$B7, Energy!$A:$A&Energy!$C:$C, Energy!$I:$I, "Missing")} -> 0 | L7: =SUM(Table5[[#This Row],[Nuclear]:[Wind]]) -> 4764.9936
A8: Bulgaria | B8: 1986 | C8: {=_xlfn.XLOOKUP($A8&$B8, 'CO2'!$A:$A&'CO2'!$C:$C, 'CO2'!$D:$D, "Missing")} -> 10.171546 | D8: {=_xlfn.XLOOKUP($A8&$B8, GDP!$A:$A&GDP!$C:$C, GDP!$D:$D, "Missing")} -> 10170 | E8: {=_xlfn.XLOOKUP($A8&$B8, LifeExp!$A:$A&LifeExp!$C:$C, LifeExp!$D:$D, "Missing")} -> 71.5502 | F8: {=_xlfn.XLOOKUP($A8&$B8, Energy!$A:$A&Energy!$C:$C, Energy!$D:$D, "Missing")} -> 13440.68 | G8: {=_xlfn.XLOOKUP($A8&$B8, Energy!$A:$A&Energy!$C:$C, Energy!$F:$F, "Missing")} -> 5944.7383 | H8: {=_xlfn.XLOOKUP($A8&$B8, Energy!$A:$A&Energy!$C:$C, Energy!$G:$G, "Missing")} -> 3740.4893 | I8: {=_xlfn.XLOOKUP($A8&$B8, Energy!$A:$A&Energy!$C:$C, Energy!$H:$H, "Missing")} -> 720.8267 | J8: {=_xlfn.XLOOKUP($A8&$B8, Energy!$A:$A&Energy!$C:$C, Energy!$J:$J, "Missing")} -> 0 | K8: {=_xlfn.XLOOKUP($A8&$B8, Energy!$A:$A&Energy!$C:$C, Energy!$I:$I, "Missing")} -> 0 | L8: =SUM(Table5[[#This Row],[Nuclear]:[Wind]]) -> 4461.316
A9: Bulgaria | B9: 1987 | C9: {=_xlfn.XLOOKUP($A9&$B9, 'CO2'!$A:$A&'CO2'!$C:$C, 'CO2'!$D:$D, "Missing")} -> 10.168741 | D9: {=_xlfn.XLOOKUP($A9&$B9, GDP!$A:$A&GDP!$C:$C, GDP!$D:$D, "Missing")} -> 10173 | E9: {=_xlfn.XLOOKUP($A9&$B9, LifeExp!$A:$A&LifeExp!$C:$C, LifeExp!$D:$D, "Missing")} -> 71.3442 | F9: {=_xlfn.XLOOKUP($A9&$B9, Energy!$A:$A&Energy!$C:$C, Energy!$D:$D, "Missing")} -> 13409.954 | G9: {=_xlfn.XLOOKUP($A9&$B9, Energy!$A:$A&Energy!$C:$C, Energy!$F:$F, "Missing")} -> 6620.0576 | H9: {=_xlfn.XLOOKUP($A9&$B9, Energy!$A:$A&Energy!$C:$C, Energy!$G:$G, "Missing")} -> 3848.4458 | I9: {=_xlfn.XLOOKUP($A9&$B9, Energy!$A:$A&Energy!$C:$C, Energy!$H:$H, "Missing")} -> 785.1003 | J9: {=_xlfn.XLOOKUP($A9&$B9, Energy!$A:$A&Energy!$C:$C, Energy!$J:$J, "Missing")} -> 0 | K9: {=_xlfn.XLOOKUP($A9&$B9, Energy!$A:$A&Energy!$C:$C, Energy!$I:$I, "Missing")} -> 0 | L9: =SUM(Table5[[#This Row],[Nuclear]:[Wind]]) -> 4633.5461
A10: Bulgaria | B10: 1988 | C10: {=_xlfn.XLOOKUP($A10&$B10, 'CO2'!$A:$A&'CO2'!$C:$C, 'CO2'!$D:$D, "Missing")} -> 9.67279 | D10: {=_xlfn.XLOOKUP($A10&$B10, GDP!$A:$A&GDP!$C:$C, GDP!$D:$D, "Missing")} -> 10098 | E10: {=_xlfn.XLOOKUP($A10&$B10, LifeExp!$A:$A&LifeExp!$C:$C, LifeExp!$D:$D, "Missing")} -> 71.4156 | F10: {=_xlfn.XLOOKUP($A10&$B10, Energy!$A:$A&Energy!$C:$C, Energy!$D:$D, "Missing")} -> 12479.406 | G10: {=_xlfn.XLOOKUP($A10&$B10, Energy!$A:$A&Energy!$C:$C, Energy!$F:$F, "Missing")} -> 6424.0254 | H10: {=_xlfn.XLOOKUP($A10&$B10, Energy!$A:$A&Energy!$C:$C, Energy!$G:$G, "Missing")} -> 4955.393 | I10: {=_xlfn.XLOOKUP($A10&$B10, Energy!$A:$A&Energy!$C:$C, Energy!$H:$H, "Missing")} -> 802.50775 | J10: {=_xlfn.XLOOKUP($A10&$B10, Energy!$A:$A&Energy!$C:$C, Energy!$J:$J, "Missing")} -> 0 | K10: {=_xlfn.XLOOKUP($A10&$B10, Energy!$A:$A&Energy!$C:$C, Energy!$I:$I, "Missing")} -> 0 | L10: =SUM(Table5[[#This Row],[Nuclear]:[Wind]]) -> 5757.9007
A11: Bulgaria | B11: 1989 | C11: {=_xlfn.XLOOKUP($A11&$B11, 'CO2'!$A:$A&'CO2'!$C:$C, 'CO2'!$D:$D, "Missing")} -> 9.675856 | D11: {=_xlfn.XLOOKUP($A11&$B11, GDP!$A:$A&GDP!$C:$C, GDP!$D:$D, "Missing")} -> 9908 | E11: {=_xlfn.XLOOKUP($A11&$B11, LifeExp!$A:$A&LifeExp!$C:$C, LifeExp!$D:$D, "Missing")} -> 71.4801 | F11: {=_xlfn.XLOOKUP($A11&$B11, Energy!$A:$A&Energy!$C:$C, Energy!$D:$D, "Missing")} -> 12807.283 | G11: {=_xlfn.XLOOKUP($A11&$B11, Energy!$A:$A&Energy!$C:$C, Energy!$F:$F, "Missing")} -> 6649.584 | H11: {=_xlfn.XLOOKUP($A11&$B11, Energy!$A:$A&Energy!$C:$C, Energy!$G:$G, "Missing")} -> 4527.6816 | I11: {=_xlfn.XLOOKUP($A11&$B11, Energy!$A:$A&Energy!$C:$C, Energy!$H:$H, "Missing")} -> 836.46783 | J11: {=_xlfn.XLOOKUP($A11&$B11, Energy!$A:$A&Energy!$C:$C, Energy!$J:$J, "Missing")} -> 0 | K11: {=_xlfn.XLOOKUP($A11&$B11, Energy!$A:$A&Energy!$C:$C, Energy!$I:$I, "Missing")} -> 0 | L11: =SUM(Table5[[#This Row],[Nuclear]:[Wind]]) -> 5364.1494
A12: Bulgaria | B12: 1990 | C12: {=_xlfn.XLOOKUP($A12&$B12, 'CO2'!$A:$A&'CO2'!$C:$C, 'CO2'!$D:$D, "Missing")} -> 8.686779 | D12: {=_xlfn.XLOOKUP($A12&$B12, GDP!$A:$A&GDP!$C:$C, GDP!$D:$D, "Missing")} -> 8922 | E12: {=_xlfn.XLOOKUP($A12&$B12, LifeExp!$A:$A&LifeExp!$C:$C, LifeExp!$D:$D, "Missing")} -> 71.3213 | F12: {=_xlfn.XLOOKUP($A12&$B12, Energy!$A:$A&Energy!$C:$C, Energy!$D:$D, "Missing")} -> 10887.999 | G12: {=_xlfn.XLOOKUP($A12&$B12, Energy!$A:$A&Energy!$C:$C, Energy!$F:$F, "Missing")} -> 7142.925 | H12: {=_xlfn.XLOOKUP($A12&$B12, Energy!$A:$A&Energy!$C:$C, Energy!$G:$G, "Missing")} -> 4617.368 | I12: {=_xlfn.XLOOKUP($A12&$B12, Energy!$A:$A&Energy!$C:$C, Energy!$H:$H, "Missing")} -> 513.2158 | J12: {=_xlfn.XLOOKUP($A12&$B12, Energy!$A:$A&Energy!$C:$C, Energy!$J:$J, "Missing")} -> 0 | K12: {=_xlfn.XLOOKUP($A12&$B12, Energy!$A:$A&Energy!$C:$C, Energy!$I:$I, "Missing")} -> 0 | L12: =SUM(Table5[[#This Row],[Nuclear]:[Wind]]) -> 5130.5838
A13: Bulgaria | B13: 1991 | C13: {=_xlfn.XLOOKUP($A13&$B13, 'CO2'!$A:$A&'CO2'!$C:$C, 'CO2'!$D:$D, "Missing")} -> 7.0747633 | D13: {=_xlfn.XLOOKUP($A13&$B13, GDP!$A:$A&GDP!$C:$C, GDP!$D:$D, "Missing")} -> 8319.673 | E13: {=_xlfn.XLOOKUP($A13&$B13, LifeExp!$A:$A&LifeExp!$C:$C, LifeExp!$D:$D, "Missing")} -> 71.1938 | F13: {=_xlfn.XLOOKUP($A13&$B13, Energy!$A:$A&Energy!$C:$C, Energy!$D:$D, "Missing")} -> 9873.93 | G13: {=_xlfn.XLOOKUP($A13&$B13, Energy!$A:$A&Energy!$C:$C, Energy!$F:$F, "Missing")} -> 6120.14 | H13: {=_xlfn.XLOOKUP($A13&$B13, Energy!$A:$A&Energy!$C:$C, Energy!$G:$G, "Missing")} -> 4211.4844 | I13: {=_xlfn.XLOOKUP($A13&$B13, Energy!$A:$A&Energy!$C:$C, Energy!$H:$H, "Missing")} -> 724.4878 | J13: {=_xlfn.XLOOKUP($A13&$B13, Energy!$A:$A&Energy!$C:$C, Energy!$J:$J, "Missing")} -> 0 | K13: {=_xlfn.XLOOKUP($A13&$B13, Energy!$A:$A&Energy!$C:$C, Energy!$I:$I, "Missing")} -> 0 | L13: =SUM(Table5[[#This Row],[Nuclear]:[Wind]]) -> 4935.9722
... A451: United States | B451: 2024 | C451: {=_xlfn.XLOOKUP($A451&$B451, 'CO2'!$A:$A&'CO2'!$C:$C, 'CO2'!$D:$D, "Missing")} -> 14.197287 | D451: {=_xlfn.XLOOKUP($A451&$B451, GDP!$A:$A&GDP!$C:$C, GDP!$D:$D, "Missing")} -> Missing | E451: {=_xlfn.XLOOKUP($A451&$B451, LifeExp!$A:$A&LifeExp!$C:$C, LifeExp!$D:$D, "Missing")} -> Missing | F451: {=_xlfn.XLOOKUP($A451&$B451, Energy!$A:$A&Energy!$C:$C, Energy!$D:$D, "Missing")} -> 6356.277 | G451: {=_xlfn.XLOOKUP($A451&$B451, Energy!$A:$A&Energy!$C:$C, Energy!$F:$F, "Missing")} -> 26118.408 | H451: {=_xlfn.XLOOKUP($A451&$B451, Energy!$A:$A&Energy!$C:$C, Energy!$G:$G, "Missing")} -> 5812.0874 | I451: {=_xlfn.XLOOKUP($A451&$B451, Energy!$A:$A&Energy!$C:$C, Energy!$H:$H, "Missing")} -> 1685.5269 | J451: {=_xlfn.XLOOKUP($A451&$B451, Energy!$A:$A&Energy!$C:$C, Energy!$J:$J, "Missing")} -> 2162.256 | K451: {=_xlfn.XLOOKUP($A451&$B451, Energy!$A:$A&Energy!$C:$C, Energy!$I:$I, "Missing")} -> 3234.1384 | L451: =SUM(Table5[[#This Row],[Nuclear]:[Wind]]) -> 12894.009

Sheet EDA_Stats
A3: Row Labels | B3: Average of CO2_Per_Capita | C3: StdDev of CO2_Per_Capita | D3: Var of CO2_Per_Capita | E3: Average of GDP_Per_Capita | F3: StdDev of GDP_Per_Capita | G3: Var of GDP_Per_Capita | H3: COV_CO2_Per_Capita | I3: COV_GDP_Per_Capita
A4: Bulgaria | B4: 7.1859219 | C4: 1.5275698 | D4: 2.3334696 | E4: 12064.037 | F4: 3821.2678 | G4: 14602087 | H4: {=C4:C13/B4:B13} -> 0.21257813 | I4: {=F4:F13/E4:E13} -> 0.31674867
A5: China | B5: 4.4109674 | C5: 2.4223036 | D5: 5.8675548 | E5: 7300.4309 | F5: 5201.2726 | G5: 27053237 | H5: 0.54915473 | I5: 0.71246104
A6: Denmark | B6: 9.3210267 | C6: 2.5472699 | D6: 6.488584 | E6: 37532.19 | F6: 8006.2126 | G6: 64099440 | H6: 0.27328212 | I6: 0.21331589
A7: France | B7: 6.3548773 | C7: 1.1966137 | D7: 1.4318844 | E7: 32173.812 | F7: 5085.3618 | G7: 25860905 | H7: 0.18829848 | I7: 0.15805904
A8: Germany | B8: 10.920302 | C8: 1.8271841 | D8: 3.3386017 | E8: 34279.045 | F8: 8455.9652 | G8: 71503347 | H8: 0.16731993 | I8: 0.2466803
A9: Ireland | B9: 9.0610429 | C9: 1.6357214 | D9: 2.6755846 | E9: 36225.107 | F9: 16588.155 | G9: 2.7516689e+08 | H9: 0.18052242 | I9: 0.45791874
A10: Italy | B10: 6.9909891 | C10: 1.0506483 | D10: 1.1038619 | E10: 30284.255 | F10: 5132.6656 | G10: 26344256 | H10: 0.15028608 | I10: 0.16948297
A11: Netherlands | B11: 10.087771 | C11: 1.3297506 | D11: 1.7682366 | E11: 36233.197 | F11: 8920.1749 | G11: 79569520 | H11: 0.13181808 | I11: 0.2461879
A12: Spain | B12: 6.0927114 | C12: 1.0856792 | D12: 1.1786994 | E12: 25438.367 | F12: 7202.5711 | G12: 51877031 | H12: 0.17819312 | I12: 0.28313811
A13: United States | B13: 18.577035 | C13: 2.2004382 | D13: 4.8419283 | E13: 44185.578 | F13: 8629.6005 | G13: 74470005 | H13: 0.11844937 | I13: 0.19530356
A14: Grand Total | B14: 8.9002644 | C14: 4.1370541 | D14: 17.115217 | E14: 29571.602 | F14: 13831.484 | G14: 1.9130996e+08 | H14: =SUM(_xlfn.ANCHORARRAY(H4)) -> 2.1499025 | I14: =SUM(_xlfn.ANCHORARRAY(I4)) -> 2.9992962

Sheet Growth_Rates
A3: Sum of CO2_Per_Capita | B3: Column Labels
A4: Row Labels | B4: 2000 | C4: 2020 | D4: Grand Total | E4: Growth Rate
A5: Bulgaria | B5: 5.687045 | C5: 5.274422 | D5: 10.961467 | E5: {=((C5:C14-B5:B14)/B5:B14)*100} -> -7.2554903
A6: China | B6: 2.8700879 | C6: 7.64075 | D6: 10.510838 | E6: 166.22007
A7: Denmark | B7: 10.170421 | C7: 4.8528743 | D7: 15.023295 | E7: -52.284431
A8: France | B8: 6.849684 | C8: 4.271517 | D8: 11.121201 | E8: -37.639211
A9: Germany | B9: 10.990293 | C9: 7.738692 | D9: 18.728985 | E9: -29.586117
A10: Ireland | B10: 11.89966 | C10: 7.0349927 | D10: 18.934653 | E10: -40.880725
A11: Italy | B11: 8.19941 | C11: 5.0506783 | D11: 13.250088 | E11: -38.40193
A12: Netherlands | B12: 10.72025 | C12: 7.7664127 | D12: 18.486663 | E12: -27.55381
A13: Spain | B13: 7.5392795 | C13: 4.441423 | D13: 11.980702 | E13: -41.089556
A14: United States | B14: 21.39786 | C14: 13.816895 | D14: 35.214756 | E14: -35.428611
A15: Grand Total | B15: 96.32399 | C15: 67.888658 | D15: 164.21265 | E15: =SUM(_xlfn.ANCHORARRAY(E5)) -> -143.89981

Sheet Confidence_Intervals
F2: Confidence interval
A3: Row Labels | B3: Average of CO2_Per_Capita | C3: StdDev of CO2_Per_Capita | D3: Count of CO2_Per_Capita | E3: Margin of error | F3: Lower bound | G3: Higher bound
A4: 2000 | B4: 9.632399 | C4: 4.9705364 | D4: 10 | E4: =_xlfn.CONFIDENCE.T(0.05, C4, D4) -> 3.5557075 | F4: =B4 - E4 -> 6.0766915 | G4: =B4 + E4 -> 13.188107
A5: 2001 | B5: 9.7361369 | C5: 4.7960306 | D5: 10 | E5: =_xlfn.CONFIDENCE.T(0.05, C5, D5) -> 3.4308736 | F5: =B5 - E5 -> 6.3052634 | G5: =B5 + E5 -> 13.167011
A6: 2002 | B6: 9.6622842 | C6: 4.7107529 | D6: 10 | E6: =_xlfn.CONFIDENCE.T(0.05, C6, D6) -> 3.3698696 | F6: =B6 - E6 -> 6.2924146 | G6: =B6 + E6 -> 13.032154
A7: 2003 | B7: 9.8783952 | C7: 4.5779283 | D7: 10 | E7: =_xlfn.CONFIDENCE.T(0.05, C7, D7) -> 3.2748527 | F7: =B7 - E7 -> 6.6035425 | G7: =B7 + E7 -> 13.153248
A8: 2004 | B8: 9.8100678 | C8: 4.5485609 | D8: 10 | E8: =_xlfn.CONFIDENCE.T(0.05, C8, D8) -> 3.2538445 | F8: =B8 - E8 -> 6.5562233 | G8: =B8 + E8 -> 13.063912
A9: 2005 | B9: 9.796049 | C9: 4.4171312 | D9: 10 | E9: =_xlfn.CONFIDENCE.T(0.05, C9, D9) -> 3.1598253 | F9: =B9 - E9 -> 6.6362237 | G9: =B9 + E9 -> 12.955874
A10: 2006 | B10: 9.8416992 | C10: 4.2432469 | D10: 10 | E10: =_xlfn.CONFIDENCE.T(0.05, C10, D10) -> 3.035436 | F10: =B10 - E10 -> 6.8062632 | G10: =B10 + E10 -> 12.877135
A11: 2007 | B11: 9.7305685 | C11: 4.1589177 | D11: 10 | E11: =_xlfn.CONFIDENCE.T(0.05, C11, D11) -> 2.9751105 | F11: =B11 - E11 -> 6.755458 | G11: =B11 + E11 -> 12.705679
A12: 2008 | B12: 9.4731182 | C12: 3.9472417 | D12: 10 | E12: =_xlfn.CONFIDENCE.T(0.05, C12, D12) -> 2.8236866 | F12: =B12 - E12 -> 6.6494316 | G12: =B12 + E12 -> 12.296805
A13: 2009 | B13: 8.7229267 | C13: 3.6146354 | D13: 10 | E13: =_xlfn.CONFIDENCE.T(0.05, C13, D13) -> 2.5857544 | F13: =B13 - E13 -> 6.1371724 | G13: =B13 + E13 -> 11.308681
A14: 2010 | B14: 8.9386061 | C14: 3.7254017 | D14: 10 | E14: =_xlfn.CONFIDENCE.T(0.05, C14, D14) -> 2.6649918 | F14: =B14 - E14 -> 6.2736143 | G14: =B14 + E14 -> 11.603598
A15: 2011 | B15: 8.6702118 | C15: 3.4771704 | D15: 10 | E15: =_xlfn.CONFIDENCE.T(0.05, C15, D15) -> 2.4874179 | F15: =B15 - E15 -> 6.182794 | G15: =B15 + E15 -> 11.15763
... A24: 2020 | B24: 6.7888658 | C24: 2.8469806 | D24: 10 | E24: =_xlfn.CONFIDENCE.T(0.05, C24, D24) -> 2.0366072 | F24: =B24 - E24 -> 4.7522585 | G24: =B24 + E24 -> 8.825473
A25: Grand Total | B25: 8.7948914 | C25: 3.8040036 | D25: 210 | E25: =SUM(E4:E24) -> 57.544887 | F25: =SUM(F4:F24) -> 127.14783 | G25: =SUM(G4:G24) -> 242.23761

Sheet T_tests
A1: France | B1: Germany | D1: t-Test: Two-Sample Assuming Unequal Variances | I1: Population mean | J1: Sample mean | K1: StdDev | L1: Count
A2: {=_xlfn.XLOOKUP($A2&$B1, 'CO2'!$A:$A&'CO2'!$C:$C, 'CO2'!$D:$D, "Missing")} -> 6.849684 | B2: {=_xlfn.XLOOKUP($A2&$B2, 'CO2'!$A:$A&'CO2'!$C:$C, 'CO2'!$D:$D, "Missing")} -> 10.990293 | I2: 8.9002644 | J2: 6.9909891 | K2: 1.0506483 | L2: 21
A3: {=_xlfn.XLOOKUP($A3&$B2, 'CO2'!$A:$A&'CO2'!$C:$C, 'CO2'!$D:$D, "Missing")} -> 6.8707247 | B3: {=_xlfn.XLOOKUP($A3&$B3, 'CO2'!$A:$A&'CO2'!$C:$C, 'CO2'!$D:$D, "Missing")} -> 11.170651 | E3: France | F3: Germany
A4: {=_xlfn.XLOOKUP($A4&$B3, 'CO2'!$A:$A&'CO2'!$C:$C, 'CO2'!$D:$D, "Missing")} -> 6.746978 | B4: {=_xlfn.XLOOKUP($A4&$B4, 'CO2'!$A:$A&'CO2'!$C:$C, 'CO2'!$D:$D, "Missing")} -> 10.952268 | D4: Mean | E4: 5.8583625 | F4: 10.059282
A5: {=_xlfn.XLOOKUP($A5&$B4, 'CO2'!$A:$A&'CO2'!$C:$C, 'CO2'!$D:$D, "Missing")} -> 6.799168 | B5: {=_xlfn.XLOOKUP($A5&$B5, 'CO2'!$A:$A&'CO2'!$C:$C, 'CO2'!$D:$D, "Missing")} -> 10.893722 | D5: Variance | E5: 0.64991927 | F5: 0.74801561
A6: {=_xlfn.XLOOKUP($A6&$B5, 'CO2'!$A:$A&'CO2'!$C:$C, 'CO2'!$D:$D, "Missing")} -> 6.7686367 | B6: {=_xlfn.XLOOKUP($A6&$B6, 'CO2'!$A:$A&'CO2'!$C:$C, 'CO2'!$D:$D, "Missing")} -> 10.677804 | D6: Observations | E6: 21 | F6: 21 | I6: t-statistic | J6: p-value
A7: {=_xlfn.XLOOKUP($A7&$B6, 'CO2'!$A:$A&'CO2'!$C:$C, 'CO2'!$D:$D, "Missing")} -> 6.756068 | B7: {=_xlfn.XLOOKUP($A7&$B7, 'CO2'!$A:$A&'CO2'!$C:$C, 'CO2'!$D:$D, "Missing")} -> 10.57788 | D7: Hypothesized Mean Difference | E7: 0 | I7: =( J2 - I2 ) / ( K2 / SQRT(L2) ) -> -8.3276187 | J7: =_xlfn.T.DIST.2T(ABS(I7), 20) -> 6.2356428e-08
A8: {=_xlfn.XLOOKUP($A8&$B7, 'CO2'!$A:$A&'CO2'!$C:$C, 'CO2'!$D:$D, "Missing")} -> 6.5539103 | B8: {=_xlfn.XLOOKUP($A8&$B8, 'CO2'!$A:$A&'CO2'!$C:$C, 'CO2'!$D:$D, "Missing")} -> 10.849607 | D8: df | E8: 40
A9: {=_xlfn.XLOOKUP($A9&$B8, 'CO2'!$A:$A&'CO2'!$C:$C, 'CO2'!$D:$D, "Missing")} -> 6.3502436 | B9: {=_xlfn.XLOOKUP($A9&$B9, 'CO2'!$A:$A&'CO2'!$C:$C, 'CO2'!$D:$D, "Missing")} -> 10.407971 | D9: t Stat | E9: -16.282103
A10: {=_xlfn.XLOOKUP($A10&$B9, 'CO2'!$A:$A&'CO2'!$C:$C, 'CO2'!$D:$D, "Missing")} -> 6.2088747 | B10: {=_xlfn.XLOOKUP($A10&$B10, 'CO2'!$A:$A&'CO2'!$C:$C, 'CO2'!$D:$D, "Missing")} -> 10.561389 | D10: P(T<=t) one-tail | E10: 1.5076282e-19
A11: {=_xlfn.XLOOKUP($A11&$B10, 'CO2'!$A:$A&'CO2'!$C:$C, 'CO2'!$D:$D, "Missing")} -> 5.8853593 | B11: {=_xlfn.XLOOKUP($A11&$B11, 'CO2'!$A:$A&'CO2'!$C:$C, 'CO2'!$D:$D, "Missing")} -> 9.760688 | D11: t Critical one-tail | E11: 1.683851
A12: {=_xlfn.XLOOKUP($A12&$B11, 'CO2'!$A:$A&'CO2'!$C:$C, 'CO2'!$D:$D, "Missing")} -> 5.945996 | B12: {=_xlfn.XLOOKUP($A12&$B12, 'CO2'!$A:$A&'CO2'!$C:$C, 'CO2'!$D:$D, "Missing")} -> 10.22758 | D12: P(T<=t) two-tail | E12: 3.0152563e-19
A13: {=_xlfn.XLOOKUP($A13&$B12, 'CO2'!$A:$A&'CO2'!$C:$C, 'CO2'!$D:$D, "Missing")} -> 5.572035 | B13: {=_xlfn.XLOOKUP($A13&$B13, 'CO2'!$A:$A&'CO2'!$C:$C, 'CO2'!$D:$D, "Missing")} -> 9.95007 | D13: t Critical two-tail | E13: 2.0210754
A14: {=_xlfn.XLOOKUP($A14&$B13, 'CO2'!$A:$A&'CO2'!$C:$C, 'CO2'!$D:$D, "Missing")} -> 5.59021 | B14: {=_xlfn.XLOOKUP($A14&$B14, 'CO2'!$A:$A&'CO2'!$C:$C, 'CO2'!$D:$D, "Missing")} -> 10.060916
A15: {=_xlfn.XLOOKUP($A15&$B14, 'CO2'!$A:$A&'CO2'!$C:$C, 'CO2'!$D:$D, "Missing")} -> 5.591334 | B15: {=_xlfn.XLOOKUP($A15&$B15, 'CO2'!$A:$A&'CO2'!$C:$C, 'CO2'!$D:$D, "Missing")} -> 10.263195
A16: {=_xlfn.XLOOKUP($A16&$B15, 'CO2'!$A:$A&'CO2'!$C:$C, 'CO2'!$D:$D, "Missing")} -> 5.067184 | B16: {=_xlfn.XLOOKUP($A16&$B16, 'CO2'!$A:$A&'CO2'!$C:$C, 'CO2'!$D:$D, "Missing")} -> 9.739761
A17: {=_xlfn.XLOOKUP($A17&$B16, 'CO2'!$A:$A&'CO2'!$C:$C, 'CO2'!$D:$D, "Missing")} -> 5.116293 | B17: {=_xlfn.XLOOKUP($A17&$B17, 'CO2'!$A:$A&'CO2'!$C:$C, 'CO2'!$D:$D, "Missing")} -> 9.756902
A18: {=_xlfn.XLOOKUP($A18&$B17, 'CO2'!$A:$A&'CO2'!$C:$C, 'CO2'!$D:$D, "Missing")} -> 5.1545954 | B18: {=_xlfn.XLOOKUP($A18&$B18, 'CO2'!$A:$A&'CO2'!$C:$C, 'CO2'!$D:$D, "Missing")} -> 9.642186
A19: {=_xlfn.XLOOKUP($A19&$B18, 'CO2'!$A:$A&'CO2'!$C:$C, 'CO2'!$D:$D, "Missing")} -> 5.182955 | B19: {=_xlfn.XLOOKUP($A19&$B19, 'CO2'!$A:$A&'CO2'!$C:$C, 'CO2'!$D:$D, "Missing")} -> 9.441122
A20: {=_xlfn.XLOOKUP($A20&$B19, 'CO2'!$A:$A&'CO2'!$C:$C, 'CO2'!$D:$D, "Missing")} -> 4.93138 | B20: {=_xlfn.XLOOKUP($A20&$B20, 'CO2'!$A:$A&'CO2'!$C:$C, 'CO2'!$D:$D, "Missing")} -> 9.101415
A21: {=_xlfn.XLOOKUP($A21&$B20, 'CO2'!$A:$A&'CO2'!$C:$C, 'CO2'!$D:$D, "Missing")} -> 4.812466 | B21: {=_xlfn.XLOOKUP($A21&$B21, 'CO2'!$A:$A&'CO2'!$C:$C, 'CO2'!$D:$D, "Missing")} -> 8.480803
A22: {=_xlfn.XLOOKUP($A22&$B21, 'CO2'!$A:$A&'CO2'!$C:$C, 'CO2'!$D:$D, "Missing")} -> 4.271517 | B22: {=_xlfn.XLOOKUP($A22&$B22, 'CO2'!$A:$A&'CO2'!$C:$C, 'CO2'!$D:$D, "Missing")} -> 7.738692

Sheet CO2
A1: Entity | B1: Code | C1: Year | D1: CO₂ emissions per capita
A2: Afghanistan | B2: AFG | C2: 1949 | D2: 0.0019921463
A3: Afghanistan | B3: AFG | C3: 1950 | D3: 0.010837197
A4: Afghanistan | B4: AFG | C4: 1951 | D4: 0.011625335
A5: Afghanistan | B5: AFG | C5: 1952 | D5: 0.011467511
A6: Afghanistan | B6: AFG | C6: 1953 | D6: 0.013123366
A7: Afghanistan | B7: AFG | C7: 1954 | D7: 0.012945492
A8: Afghanistan | B8: AFG | C8: 1955 | D8: 0.018480647
A9: Afghanistan | B9: AFG | C9: 1956 | D9: 0.021669438
A10: Afghanistan | B10: AFG | C10: 1957 | D10: 0.034129996
A11: Afghanistan | B11: AFG | C11: 1958 | D11: 0.037801724
A12: Afghanistan | B12: AFG | C12: 1959 | D12: 0.04335994
A13: Afghanistan | B13: AFG | C13: 1960 | D13: 0.045808833
... A1288: Asia | B1288: OWID_ASI | C1288: 2024 | D1288: 4.867817
A1289: Asia (excl. China and India) | C1289: 1750 | D1289: 0
A1290: Asia (excl. China and India) | C1290: 1760 | D1290: 0
A1291: Asia (excl. China and India) | C1291: 1770 | D1291: 0
A1292: Asia (excl. China and India) | C1292: 1780 | D1292: 0
A1293: Asia (excl. China and India) | C1293: 1790 | D1293: 0
A1294: Asia (excl. China and India) | C1294: 1800 | D1294: 0
A1295: Asia (excl. China and India) | C1295: 1801 | D1295: 0
A1296: Asia (excl. China and India) | C1296: 1802 | D1296: 0
A1297: Asia (excl. China and India) | C1297: 1803 | D1297: 0
A1298: Asia (excl. China and India) | C1298: 1804 | D1298: 0
A1299: Asia (excl. China and India) | C1299: 1805 | D1299: 0
A1300: Asia (excl. China and India) | C1300: 1806 | D1300: 0
... A1518: Asia (excl. China and India) | C1518: 2024 | D1518: 4.087244
A1519: Australia | B1519: AUS | C1519: 1750 | D1519: 0
A1520: Australia | B1520: AUS | C1520: 1760 | D1520: 0
A1521: Australia | B1521: AUS | C1521: 1770 | D1521: 0
A1522: Australia | B1522: AUS | C1522: 1780 | D1522: 0
A1523: Australia | B1523: AUS | C1523: 1790 | D1523: 0
A1524: Australia | B1524: AUS | C1524: 1800 | D1524: 0
A1525: Australia | B1525: AUS | C1525: 1801 | D1525: 0
A1526: Australia | B1526: AUS | C1526: 1802 | D1526: 0
A1527: Australia | B1527: AUS | C1527: 1803 | D1527: 0
A1528: Australia | B1528: AUS | C1528: 1804 | D1528: 0
A1529: Australia | B1529: AUS | C1529: 1805 | D1529: 0.0010380151
A1530: Australia | B1530: AUS | C1530: 1806 | D1530: 0.0028337112
... A7916: Europe | B7916: OWID_EUR | C7916: 2024 | D7916: 6.541561
...

Sheet GDP
A1: Entity | B1: Code | C1: Year | D1: GDP per capita | E1: GDP per capita (Annotations)
A2: Afghanistan | B2: AFG | C2: 1950 | D2: 1156
A3: Afghanistan | B3: AFG | C3: 1951 | D3: 1170
A4: Afghanistan | B4: AFG | C4: 1952 | D4: 1189
A5: Afghanistan | B5: AFG | C5: 1953 | D5: 1240
A6: Afghanistan | B6: AFG | C6: 1954 | D6: 1245
A7: Afghanistan | B7: AFG | C7: 1955 | D7: 1246
A8: Afghanistan | B8: AFG | C8: 1956 | D8: 1278
A9: Afghanistan | B9: AFG | C9: 1957 | D9: 1253
A10: Afghanistan | B10: AFG | C10: 1958 | D10: 1298
A11: Afghanistan | B11: AFG | C11: 1959 | D11: 1307
A12: Afghanistan | B12: AFG | C12: 1960 | D12: 1326
A13: Afghanistan | B13: AFG | C13: 1961 | D13: 1309
... A4407: Dominican Republic | B4407: DOM | C4407: 2022 | D4407: 17713.52
A4408: East Asia (Maddison) | C4408: 1820 | D4408: 911.1599
A4409: East Asia (Maddison) | C4409: 1830 | D4409: 846
A4410: East Asia (Maddison) | C4410: 1840 | D4410: 849
A4411: East Asia (Maddison) | C4411: 1850 | D4411: 899.65765
A4412: East Asia (Maddison) | C4412: 1870 | D4412: 993.6216
A4413: East Asia (Maddison) | C4413: 1890 | D4413: 1048.869
A4414: East Asia (Maddison) | C4414: 1900 | D4414: 1086.2826
A4415: East Asia (Maddison) | C4415: 1910 | D4415: 1056.0726
A4416: East Asia (Maddison) | C4416: 1920 | D4416: 1215.6156
A4417: East Asia (Maddison) | C4417: 1930 | D4417: 1296.0483
A4418: East Asia (Maddison) | C4418: 1940 | D4418: 1496.2766
A4419: East Asia (Maddison) | C4419: 1950 | D4419: 1109.4408
... A4457: Eastern Europe (Maddison) | C4457: 2022 | D4457: 20656.266
A4458: Ecuador | B4458: ECU | C4458: 1870 | D4458: 760
A4459: Ecuador | B4459: ECU | C4459: 1880 | D4459: 760
